Workbook
Name CustTblsExclusionYear: [1]Tables!#REF!
Name CustTblsExclusionYear: [1]Tables!#REF!
Name input_Annual: [1]Input!$K$183
Name input_BidType: [1]Input!$K$98
Name input_BioHumiraAdj: [1]Input!$K$39
Name input_BiosimHumira: [1]Input!$K$38
Name input_BiosimStelara: [1]Input!$K$42
Name input_BioStelaraAdj: [1]Input!$K$43
Name input_client_nm: [1]Input!$K$96
Name input_CustomSP: [1]Input!$K$110
Name input_Device: [1]Input!$K$134
Name input_excl_custNDC: [1]Input!$K$148
Name input_excl_custNDC_desc: [1]Input!$M$148
Name input_excl_custNDC_rebates: [1]Input!$M$149
Name input_excl_HIV: [1]Input!$K$146
Name input_excl_nonRebatable: [1]Input!$K$147
Name input_formulary: [1]Input!$K$30
Name input_Formulary_Excls: [1]Input!$K$143
Name input_GB: [1]Input!$K$104
Name input_GF_NSP: [1]Input!$K$101
Name input_GF_NSP_mnth: [1]Input!$K$102
Name input_GF_SP: [1]Input!$L$101
Name input_GF_SP_mnth: [1]Input!$L$102
Name input_HepB: [1]Input!$K$113
Name input_HIV: [1]Input!$K$114
Name input_Institutional_NDCs: [1]Input!$K$142
Name input_Insulin: [1]Input!$K$139
Name input_IVIG: [1]Input!$K$115
Name input_LDD: [1]Input!$K$141
Name input_Lift: [1]Input!$K$121
Name input_LOB: [1]Input!$K$97
Name input_MCRPartBCov: [1]Input!$K$172
Name input_mfp: [1]Input!$K$177
Name input_MFP_AdjCurr: #REF!
Name input_MSB: [1]Input!$K$137
Name input_Narcolepsy: [1]Input!$K$116
Name input_Nausea: [1]Input!$K$117
Name input_NonFDA: [1]Input!$K$140
Name input_oGLP1: [1]Input!$K$164
Name input_oGLP1_Mbrs: [1]Input!$K$165
Name input_OTC: [1]Input!$K$133
Name input_PCSK9: [1]Input!$K$145
Name input_RebateCredit: [1]Input!$K$125
Name input_RebateDollars: [1]Input!$K$130
Name input_Repack: [1]Input!$K$136
Name input_rpt_name: [1]Input!$C$5
Name input_Shift: [1]Input!$K$123
Name input_SP: [1]Input!$K$105
Name input_spR_PCSK9: [1]Input!$K$119
Name input_Synthroid: [1]Input!$K$144
Name input_Transplant: [1]Input!$K$118
Name input_TS: [1]Input!$K$138
Name input_Vaccine: [1]Input!$K$135
Name input_WghtLossCov: [1]Input!$K$155
Name input_WghtLossCovTdy: [1]Input!$K$160
Name input_WghtLossEnhUM: [1]Input!$K$157
Name load_out: [1]Tables!$C$9
Name load_rates: [1]Tables!$C$11
Name load_shift: [1]Tables!$C$10
Name Medispan_w_Override_URL: [1]Tables!$BD$17

Sheet Rate Build-up
I1: =LEFT(I56,1) -> G | J1: =I1 -> G | K1: =J1 -> G | L1: =K1 -> G | M1: =L1 -> G | N1: =LEFT(N56,1) -> B | O1: =N1 -> B | P1: =O1 -> B | Q1: =P1 -> B | R1: =Q1 -> B
I6: Pre-Shift | Z6: ="Pre-Shift + ANNUALIZATION" -> Pre-Shift + ANNUALIZATION | AQ6: =IF([1]Input!$K$123="No","Pre-Shift + Annualization", "Annualization + SHIFT") & " + HEP C ADJ" -> Pre-Shift + Annualization + HEP C ADJ | BH6: =IF([1]Input!$K$123="No","Pre-Shift + Annualization + Hep C adj", "Annualization + Shift + Hep C adj") & " + LIFT" -> Pre-Shift + Annualization + Hep C adj + LIFT | BY6: =IF([1]Input!$K$123="No","Pre-Shift + Annualization + Hep C adj + Lift", "Annualization + Shift + Hep C adj + Lift") & " + INCREMENTAL BRAND" -> Pre-Shift + Annualization + Hep C adj + Lift + INCREMENTAL BRAND
I8: Base | Z8: Base | AQ8: Base | BH8: Base | BY8: Base | DC8: Base | DI8: Base
I9: Total $ | N9: Per Brand Script | S9: Per Total Script | Z9: Total $ | AE9: Per Brand Script | AJ9: Per Total Script | AQ9: Total $ | AV9: Per Brand Script | BA9: Per Total Script | BH9: Total $ | BM9: Per Brand Script | BR9: Per Total Script | BY9: Total $ | CD9: Per Brand Script | CI9: Per Total Script | DC9: Rejection Rate Adj | DI9: 340B Rejection Rate
B10: Mail | C10: DS | D10: SP | E10: Excl | I10: =[1]Tables!$AA$4 -> 07/27 - 06/28 | J10: =[1]Tables!$AA$5 -> 07/28 - 06/29 | K10: =[1]Tables!$AA$6 -> 07/29 - 06/30 | L10: =[1]Tables!$AA$7 -> 07/30 - 06/31 | M10: =[1]Tables!$AA$8 -> 07/31 - 06/32 | N10: =[1]Tables!$AA$4 -> 07/27 - 06/28 | O10: =[1]Tables!$AA$5 -> 07/28 - 06/29 | P10: =[1]Tables!$AA$6 -> 07/29 - 06/30 | Q10: =[1]Tables!$AA$7 -> 07/30 - 06/31 | R10: =[1]Tables!$AA$8 -> 07/31 - 06/32 | S10: =[1]Tables!$AA$4 -> 07/27 - 06/28 | T10: =[1]Tables!$AA$5 -> 07/28 - 06/29 | U10: =[1]Tables!$AA$6 -> 07/29 - 06/30 | V10: =[1]Tables!$AA$7 -> 07/30 - 06/31 | W10: =[1]Tables!$AA$8 -> 07/31 - 06/32 | Z10: =[1]Tables!$AA$4 -> 07/27 - 06/28 | AA10: =[1]Tables!$AA$5 -> 07/28 - 06/29 | AB10: =[1]Tables!$AA$6 -> 07/29 - 06/30 | AC10: =[1]Tables!$AA$7 -> 07/30 - 06/31 | AD10: =[1]Tables!$AA$8 -> 07/31 - 06/32 | AE10: =[1]Tables!$AA$4 -> 07/27 - 06/28 | AF10: =[1]Tables!$AA$5 -> 07/28 - 06/29 | AG10: =[1]Tables!$AA$6 -> 07/29 - 06/30 | AH10: =[1]Tables!$AA$7 -> 07/30 - 06/31 | AI10: =[1]Tables!$AA$8 -> 07/31 - 06/32 | AJ10: =[1]Tables!$AA$4 -> 07/27 - 06/28 | AK10: =[1]Tables!$AA$5 -> 07/28 - 06/29 | AL10: =[1]Tables!$AA$6 -> 07/29 - 06/30 | AM10: =[1]Tables!$AA$7 -> 07/30 - 06/31 | AN10: =[1]Tables!$AA$8 -> 07/31 - 06/32 | AQ10: =[1]Tables!$AA$4 -> 07/27 - 06/28 | AR10: =[1]Tables!$AA$5 -> 07/28 - 06/29 | AS10: =[1]Tables!$AA$6 -> 07/29 - 06/30 | AT10: =[1]Tables!$AA$7 -> 07/30 - 06/31 | AU10: =[1]Tables!$AA$8 -> 07/31 - 06/32 | AV10: =[1]Tables!$AA$4 -> 07/27 - 06/28 | AW10: =[1]Tables!$AA$5 -> 07/28 - 06/29 | AX10: =[1]Tables!$AA$6 -> 07/29 - 06/30 | AY10: =[1]Tables!$AA$7 -> 07/30 - 06/31 | AZ10: =[1]Tables!$AA$8 -> 07/31 - 06/32 | BA10: =[1]Tables!$AA$4 -> 07/27 - 06/28 | BB10: =[1]Tables!$AA$5 -> 07/28 - 06/29 | BC10: =[1]Tables!$AA$6 -> 07/29 - 06/30 | BD10: =[1]Tables!$AA$7 -> 07/30 - 06/31 | BE10: =[1]Tables!$AA$8 -> 07/31 - 06/32 | BH10: =[1]Tables!$AA$4 -> 07/27 - 06/28 | BI10: =[1]Tables!$AA$5 -> 07/28 - 06/29 | BJ10: =[1]Tables!$AA$6 -> 07/29 - 06/30 | BK10: =[1]Tables!$AA$7 -> 07/30 - 06/31 | BL10: =[1]Tables!$AA$8 -> 07/31 - 06/32 | BM10: =[1]Tables!$AA$4 -> 07/27 - 06/28 | BN10: =[1]Tables!$AA$5 -> 07/28 - 06/29 | BO10: =[1]Tables!$AA$6 -> 07/29 - 06/30 | BP10: =[1]Tables!$AA$7 -> 07/30 - 06/31 | BQ10: =[1]Tables!$AA$8 -> 07/31 - 06/32 | BR10: =[1]Tables!$AA$4 -> 07/27 - 06/28 | BS10: =[1]Tables!$AA$5 -> 07/28 - 06/29 | BT10: =[1]Tables!$AA$6 -> 07/29 - 06/30 | BU10: =[1]Tables!$AA$7 -> 07/30 - 06/31 | BV10: =[1]Tables!$AA$8 -> 07/31 - 06/32 | BY10: =[1]Tables!$AA$4 -> 07/27 - 06/28 | BZ10: =[1]Tables!$AA$5 -> 07/28 - 06/29 | CA10: =[1]Tables!$AA$6 -> 07/29 - 06/30 | CB10: =[1]Tables!$AA$7 -> 07/30 - 06/31 | CC10: =[1]Tables!$AA$8 -> 07/31 - 06/32 | CD10: =[1]Tables!$AA$4 -> 07/27 - 06/28 | CE10: =[1]Tables!$AA$5 -> 07/28 - 06/29 | CF10: =[1]Tables!$AA$6 -> 07/29 - 06/30 | CG10: =[1]Tables!$AA$7 -> 07/30 - 06/31 | CH10: =[1]Tables!$AA$8 -> 07/31 - 06/32 | CI10: =[1]Tables!$AA$4 -> 07/27 - 06/28 | CJ10: =[1]Tables!$AA$5 -> 07/28 - 06/29 | CK10: =[1]Tables!$AA$6 -> 07/29 - 06/30 | CL10: =[1]Tables!$AA$7 -> 07/30 - 06/31 | CM10: =[1]Tables!$AA$8 -> 07/31 - 06/32 | DC10: =[1]Tables!$AA$4 -> 07/27 - 06/28 | DD10: =[1]Tables!$AA$5 -> 07/28 - 06/29 | DE10: =[1]Tables!$AA$6 -> 07/29 - 06/30 | DF10: =[1]Tables!$AA$7 -> 07/30 - 06/31 | DG10: =[1]Tables!$AA$8 -> 07/31 - 06/32 | DI10: =[1]Tables!$AA$4 -> 07/27 - 06/28 | DJ10: =[1]Tables!$AA$5 -> 07/28 - 06/29 | DK10: =[1]Tables!$AA$6 -> 07/29 - 06/30 | DL10: =[1]Tables!$AA$7 -> 07/30 - 06/31 | DM10: =[1]Tables!$AA$8 -> 07/31 - 06/32
B11: R | C11: 30 | D11: N | E11: N | F11: Y | H11: Retail 30 | I11: {=SUMIFS(INDIRECT('[1]RA Output'!BP$1), rng_out_mail_ind, $B11, rng_out_ds, $C11, rng_out_sel_sp_ind, $D11, rng_out_sel_excl_ind,$E11) + SUMIFS(INDIRECT('[1]RA Output'!BP$1), rng_out_mail_ind, $B11, rng_out_ds, $C11, rng_out_sel_sp_ind, $D11, rng_out_sel_excl_ind,$F11, rng_out_sel_excl_yr_ind, ">0", rng_out_sel_excl_ind,$F11) + IF([1]Tables!$C$16=[1]Tables!$CF$4, SUMIFS(INDIRECT('[1]RA Output'!BP$1), rng_out_mail_ind, $B11, rng_out_ds, $C11, rng_out_sel_sp_ind, $D11, rng_out_sel_excl_ind,$F11,rng_out_sel_excl_yr_ind, ""), 0)} -> #REF! | J11: {=SUMIFS(INDIRECT('[1]RA Output'!BQ$1), rng_out_mail_ind, $B11, rng_out_ds, $C11, rng_out_sel_sp_ind, $D11, rng_out_sel_excl_ind,$E11) + SUMIFS(INDIRECT('[1]RA Output'!BQ$1), rng_out_mail_ind, $B11, rng_out_ds, $C11, rng_out_sel_sp_ind, $D11, rng_out_sel_excl_ind,$F11, rng_out_sel_excl_yr_ind, ">0", rng_out_sel_excl_ind,$F11) + IF([1]Tables!$C$16=[1]Tables!$CF$4, SUMIFS(INDIRECT('[1]RA Output'!BQ$1), rng_out_mail_ind, $B11, rng_out_ds, $C11, rng_out_sel_sp_ind, $D11, rng_out_sel_excl_ind,$F11,rng_out_sel_excl_yr_ind, ""), 0)} -> #REF! | K11: {=SUMIFS(INDIRECT('[1]RA Output'!BR$1), rng_out_mail_ind, $B11, rng_out_ds, $C11, rng_out_sel_sp_ind, $D11, rng_out_sel_excl_ind,$E11) + SUMIFS(INDIRECT('[1]RA Output'!BR$1), rng_out_mail_ind, $B11, rng_out_ds, $C11, rng_out_sel_sp_ind, $D11, rng_out_sel_excl_ind,$F11, rng_out_sel_excl_yr_ind, ">0", rng_out_sel_excl_ind,$F11) + IF([1]Tables!$C$16=[1]Tables!$CF$4, SUMIFS(INDIRECT('[1]RA Output'!BR$1), rng_out_mail_ind, $B11, rng_out_ds, $C11, rng_out_sel_sp_ind, $D11, rng_out_sel_excl_ind,$F11,rng_out_sel_excl_yr_ind, ""), 0)} -> #REF! | L11: {=SUMIFS(INDIRECT('[1]RA Output'!BS$1), rng_out_mail_ind, $B11, rng_out_ds, $C11, rng_out_sel_sp_ind, $D11, rng_out_sel_excl_ind,$E11) + SUMIFS(INDIRECT('[1]RA Output'!BS$1), rng_out_mail_ind, $B11, rng_out_ds, $C11, rng_out_sel_sp_ind, $D11, rng_out_sel_excl_ind,$F11, rng_out_sel_excl_yr_ind, ">0", rng_out_sel_excl_ind,$F11) + IF([1]Tables!$C$16=[1]Tables!$CF$4, SUMIFS(INDIRECT('[1]RA Output'!BS$1), rng_out_mail_ind, $B11, rng_out_ds, $C11, rng_out_sel_sp_ind, $D11, rng_out_sel_excl_ind,$F11,rng_out_sel_excl_yr_ind, ""), 0)} -> #REF! | M11: {=SUMIFS(INDIRECT('[1]RA Output'!BT$1), rng_out_mail_ind, $B11, rng_out_ds, $C11, rng_out_sel_sp_ind, $D11, rng_out_sel_excl_ind,$E11) + SUMIFS(INDIRECT('[1]RA Output'!BT$1), rng_out_mail_ind, $B11, rng_out_ds, $C11, rng_out_sel_sp_ind, $D11, rng_out_sel_excl_ind,$F11, rng_out_sel_excl_yr_ind, ">0", rng_out_sel_excl_ind,$F11) + IF([1]Tables!$C$16=[1]Tables!$CF$4, SUMIFS(INDIRECT('[1]RA Output'!BT$1), rng_out_mail_ind, $B11, rng_out_ds, $C11, rng_out_sel_sp_ind, $D11, rng_out_sel_excl_ind,$F11,rng_out_sel_excl_yr_ind, ""), 0)} -> #REF! | N11: =IFERROR(I11/N$58, 0) -> 0 | O11: =IFERROR(J11/O$58, 0) -> 0 | P11: =IFERROR(K11/P$58, 0) -> 0 | Q11: =IFERROR(L11/Q$58, 0) -> 0 | R11: =IFERROR(M11/R$58, 0) -> 0 | S11: =IFERROR(I11/S$58, 0) -> 0 | T11: =IFERROR(J11/T$58, 0) -> 0 | U11: =IFERROR(K11/U$58, 0) -> 0 | V11: =IFERROR(L11/V$58, 0) -> 0 | W11: =IFERROR(M11/W$58, 0) -> 0 | Y11: Retail 30 | Z11: =IFERROR(I11/[1]Tables!$AT$4,0) -> 0 | AA11: =IFERROR(J11/[1]Tables!$AT$4,0) -> 0 | AB11: =IFERROR(K11/[1]Tables!$AT$4,0) -> 0 | AC11: =IFERROR(L11/[1]Tables!$AT$4,0) -> 0 | AD11: =IFERROR(M11/[1]Tables!$AT$4,0) -> 0 | AE11: =IFERROR(N11/[1]Tables!$AT$4, 0) -> 0 | AF11: =IFERROR(O11/[1]Tables!$AT$4, 0) -> 0 | AG11: =IFERROR(P11/[1]Tables!$AT$4, 0) -> 0 | AH11: =IFERROR(Q11/[1]Tables!$AT$4, 0) -> 0 | AI11: =IFERROR(R11/[1]Tables!$AT$4, 0) -> 0 | AJ11: =IFERROR(S11/[1]Tables!$AT$4,0) -> 0 | AK11: =IFERROR(T11/[1]Tables!$AT$4,0) -> 0 | AL11: =IFERROR(U11/[1]Tables!$AT$4,0) -> 0 | AM11: =IFERROR(V11/[1]Tables!$AT$4,0) -> 0 | AN11: =IFERROR(W11/[1]Tables!$AT$4,0) -> 0 | AP11: Retail 30 | AQ11: {=(SUMIFS(INDIRECT('[1]RA Output'!CP$1), rng_out_mail_ind, $B11, rng_out_ds, $C11, rng_out_sel_sp_ind, $D11, rng_out_sel_excl_ind,$E11) + SUMIFS(INDIRECT('[1]RA Output'!CP$1), rng_out_mail_ind, $B11, rng_out_ds, $C11, rng_out_sel_sp_ind, $D11, rng_out_sel_excl_ind,$F11, rng_out_sel_excl_yr_ind, ">0", rng_out_sel_excl_ind,$F11) + IF([1]Tables!$C$16=[1]Tables!$CF$4, SUMIFS(INDIRECT('[1]RA Output'!CP$1), rng_out_mail_ind, $B11, rng_out_ds, $C11, rng_out_sel_sp_ind, $D11, rng_out_sel_excl_ind,$F11,rng_out_sel_excl_yr_ind, ""), 0))/[1]Tables!$AT$4} -> #REF! | AR11: {=(SUMIFS(INDIRECT('[1]RA Output'!CQ$1), rng_out_mail_ind, $B11, rng_out_ds, $C11, rng_out_sel_sp_ind, $D11, rng_out_sel_excl_ind,$E11) + SUMIFS(INDIRECT('[1]RA Output'!CQ$1), rng_out_mail_ind, $B11, rng_out_ds, $C11, rng_out_sel_sp_ind, $D11, rng_out_sel_excl_ind,$F11, rng_out_sel_excl_yr_ind, ">0", rng_out_sel_excl_ind,$F11) + IF([1]Tables!$C$16=[1]Tables!$CF$4, SUMIFS(INDIRECT('[1]RA Output'!CQ$1), rng_out_mail_ind, $B11, rng_out_ds, $C11, rng_out_sel_sp_ind, $D11, rng_out_sel_excl_ind,$F11,rng_out_sel_excl_yr_ind, ""), 0))/[1]Tables!$AT$4} -> #REF! | AS11: {=(SUMIFS(INDIRECT('[1]RA Output'!CR$1), rng_out_mail_ind, $B11, rng_out_ds, $C11, rng_out_sel_sp_ind, $D11, rng_out_sel_excl_ind,$E11) + SUMIFS(INDIRECT('[1]RA Output'!CR$1), rng_out_mail_ind, $B11, rng_out_ds, $C11, rng_out_sel_sp_ind, $D11, rng_out_sel_excl_ind,$F11, rng_out_sel_excl_yr_ind, ">0", rng_out_sel_excl_ind,$F11) + IF([1]Tables!$C$16=[1]Tables!$CF$4, SUMIFS(INDIRECT('[1]RA Output'!CR$1), rng_out_mail_ind, $B11, rng_out_ds, $C11, rng_out_sel_sp_ind, $D11, rng_out_sel_excl_ind,$F11,rng_out_sel_excl_yr_ind, ""), 0))/[1]Tables!$AT$4} -> #REF! | AT11: {=(SUMIFS(INDIRECT('[1]RA Output'!CS$1), rng_out_mail_ind, $B11, rng_out_ds, $C11, rng_out_sel_sp_ind, $D11, rng_out_sel_excl_ind,$E11) + SUMIFS(INDIRECT('[1]RA Output'!CS$1), rng_out_mail_ind, $B11, rng_out_ds, $C11, rng_out_sel_sp_ind, $D11, rng_out_sel_excl_ind,$F11, rng_out_sel_excl_yr_ind, ">0", rng_out_sel_excl_ind,$F11) + IF([1]Tables!$C$16=[1]Tables!$CF$4, SUMIFS(INDIRECT('[1]RA Output'!CS$1), rng_out_mail_ind, $B11, rng_out_ds, $C11, rng_out_sel_sp_ind, $D11, rng_out_sel_excl_ind,$F11,rng_out_sel_excl_yr_ind, ""), 0))/[1]Tables!$AT$4} -> #REF! | AU11: {=(SUMIFS(INDIRECT('[1]RA Output'!CT$1), rng_out_mail_ind, $B11, rng_out_ds, $C11, rng_out_sel_sp_ind, $D11, rng_out_sel_excl_ind,$E11) + SUMIFS(INDIRECT('[1]RA Output'!CT$1), rng_out_mail_ind, $B11, rng_out_ds, $C11, rng_out_sel_sp_ind, $D11, rng_out_sel_excl_ind,$F11, rng_out_sel_excl_yr_ind, ">0", rng_out_sel_excl_ind,$F11) + IF([1]Tables!$C$16=[1]Tables!$CF$4, SUMIFS(INDIRECT('[1]RA Output'!CT$1), rng_out_mail_ind, $B11, rng_out_ds, $C11, rng_out_sel_sp_ind, $D11, rng_out_sel_excl_ind,$F11,rng_out_sel_excl_yr_ind, ""), 0))/[1]Tables!$AT$4} -> #REF! | AV11: =IFERROR(AQ11/AV$58, 0) -> 0 | AW11: =IFERROR(AR11/AW$58, 0) -> 0 | AX11: =IFERROR(AS11/AX$58, 0) -> 0 | AY11: =IFERROR(AT11/AY$58, 0) -> 0 | AZ11: =IFERROR(AU11/AZ$58, 0) -> 0 | BA11: =IFERROR(AQ11/BA$58, 0) -> 0 | BB11: =IFERROR(AR11/BB$58, 0) -> 0 | BC11: =IFERROR(AS11/BC$58, 0) -> 0 | BD11: =IFERROR(AT11/BD$58, 0) -> 0 | BE11: =IFERROR(AU11/BE$58, 0) -> 0 | BG11: Retail 30 | BH11: {=(SUMIFS(INDIRECT('[1]RA Output'!DP$1), rng_out_mail_ind, $B11, rng_out_ds, $C11, rng_out_sel_sp_ind, $D11, rng_out_sel_excl_ind,$E11) + SUMIFS(INDIRECT('[1]RA Output'!DP$1), rng_out_mail_ind, $B11, rng_out_ds, $C11, rng_out_sel_sp_ind, $D11, rng_out_sel_excl_ind,$F11, rng_out_sel_excl_yr_ind, ">0") + IF([1]Tables!$C$16=[1]Tables!$CF$4, SUMIFS(INDIRECT('[1]RA Output'!DP$1), rng_out_mail_ind, $B11, rng_out_ds, $C11, rng_out_sel_sp_ind, $D11, rng_out_sel_excl_ind,$F11,rng_out_sel_excl_yr_ind, ""), 0))/[1]Tables!$AT$4} -> #REF! | BI11: {=(SUMIFS(INDIRECT('[1]RA Output'!DQ$1), rng_out_mail_ind, $B11, rng_out_ds, $C11, rng_out_sel_sp_ind, $D11, rng_out_sel_excl_ind,$E11) + SUMIFS(INDIRECT('[1]RA Output'!DQ$1), rng_out_mail_ind, $B11, rng_out_ds, $C11, rng_out_sel_sp_ind, $D11, rng_out_sel_excl_ind,$F11, rng_out_sel_excl_yr_ind, ">0") + IF([1]Tables!$C$16=[1]Tables!$CF$4, SUMIFS(INDIRECT('[1]RA Output'!DQ$1), rng_out_mail_ind, $B11, rng_out_ds, $C11, rng_out_sel_sp_ind, $D11, rng_out_sel_excl_ind,$F11,rng_out_sel_excl_yr_ind, ""), 0))/[1]Tables!$AT$4} -> #REF! | BJ11: {=(SUMIFS(INDIRECT('[1]RA Output'!DR$1), rng_out_mail_ind, $B11, rng_out_ds, $C11, rng_out_sel_sp_ind, $D11, rng_out_sel_excl_ind,$E11) + SUMIFS(INDIRECT('[1]RA Output'!DR$1), rng_out_mail_ind, $B11, rng_out_ds, $C11, rng_out_sel_sp_ind, $D11, rng_out_sel_excl_ind,$F11, rng_out_sel_excl_yr_ind, ">0") + IF([1]Tables!$C$16=[1]Tables!$CF$4, SUMIFS(INDIRECT('[1]RA Output'!DR$1), rng_out_mail_ind, $B11, rng_out_ds, $C11, rng_out_sel_sp_ind, $D11, rng_out_sel_excl_ind,$F11,rng_out_sel_excl_yr_ind, ""), 0))/[1]Tables!$AT$4} -> #REF! | BK11: {=(SUMIFS(INDIRECT('[1]RA Output'!DS$1), rng_out_mail_ind, $B11, rng_out_ds, $C11, rng_out_sel_sp_ind, $D11, rng_out_sel_excl_ind,$E11) + SUMIFS(INDIRECT('[1]RA Output'!DS$1), rng_out_mail_ind, $B11, rng_out_ds, $C11, rng_out_sel_sp_ind, $D11, rng_out_sel_excl_ind,$F11, rng_out_sel_excl_yr_ind, ">0") + IF([1]Tables!$C$16=[1]Tables!$CF$4, SUMIFS(INDIRECT('[1]RA Output'!DS$1), rng_out_mail_ind, $B11, rng_out_ds, $C11, rng_out_sel_sp_ind, $D11, rng_out_sel_excl_ind,$F11,rng_out_sel_excl_yr_ind, ""), 0))/[1]Tables!$AT$4} -> #REF! | BL11: {=(SUMIFS(INDIRECT('[1]RA Output'!DT$1), rng_out_mail_ind, $B11, rng_out_ds, $C11, rng_out_sel_sp_ind, $D11, rng_out_sel_excl_ind,$E11) + SUMIFS(INDIRECT('[1]RA Output'!DT$1), rng_out_mail_ind, $B11, rng_out_ds, $C11, rng_out_sel_sp_ind, $D11, rng_out_sel_excl_ind,$F11, rng_out_sel_excl_yr_ind, ">0") + IF([1]Tables!$C$16=[1]Tables!$CF$4, SUMIFS(INDIRECT('[1]RA Output'!DT$1), rng_out_mail_ind, $B11, rng_out_ds, $C11, rng_out_sel_sp_ind, $D11, rng_out_sel_excl_ind,$F11,rng_out_sel_excl_yr_ind, ""), 0))/[1]Tables!$AT$4} -> #REF! | BM11: =IFERROR(BH11/BM$58, 0) -> 0 | BN11: =IFERROR(BI11/BN$58, 0) -> 0 | BO11: =IFERROR(BJ11/BO$58, 0) -> 0 | BP11: =IFERROR(BK11/BP$58, 0) -> 0 | BQ11: =IFERROR(BL11/BQ$58, 0) -> 0 | BR11: =IFERROR(BH11/BR$58, 0) -> 0 | BS11: =IFERROR(BI11/BS$58, 0) -> 0 | BT11: =IFERROR(BJ11/BT$58, 0) -> 0 | BU11: =IFERROR(BK11/BU$58, 0) -> 0 | BV11: =IFERROR(BL11/BV$58, 0) -> 0 | BX11: Retail 30 | BY11: =CD11*CD58 -> #VALUE! | BZ11: =CE11*CE58 -> #VALUE! | CA11: =CF11*CF58 -> #VALUE! | CB11: =CG11*CG58 -> #VALUE! | CC11: =CH11*CH58 -> #VALUE! | CD11: =BM11-DC11 -> 0 | CE11: =BN11-DD11 -> 0 | CF11: =BO11-DE11 -> 0 | CG11: =BP11-DF11 -> 0 | CH11: =BQ11-DG11 -> 0 | CI11: =IFERROR(BY11/CI58, 0) -> 0 | CJ11: =IFERROR(BZ11/CJ58, 0) -> 0 | CK11: =IFERROR(CA11/CK58, 0) -> 0 | CL11: =IFERROR(CB11/CL58, 0) -> 0 | CM11: =IFERROR(CC11/CM58, 0) -> 0 | DC11: {=IFERROR(BM11-BM11*BR67*(1-INDEX([1]Tables!$EA$4:$EE$60,MATCH([1]Tables!$C$22&$BX11,[1]Tables!$EA$4:$EA$60,0),[1]Tables!$EE$1))*(1-DI11)/CD58, 0)} -> 0 | DD11: {=IFERROR(BN11-BN11*BS67*(1-INDEX([1]Tables!$EA$4:$EE$60,MATCH([1]Tables!$C$22&$BX11,[1]Tables!$EA$4:$EA$60,0),[1]Tables!$EE$1))*(1-DJ11)/CE58, 0)} -> 0 | DE11: {=IFERROR(BO11-BO11*BT67*(1-INDEX([1]Tables!$EA$4:$EE$60,MATCH([1]Tables!$C$22&$BX11,[1]Tables!$EA$4:$EA$60,0),[1]Tables!$EE$1))*(1-DK11)/CF58, 0)} -> 0 | DF11: {=IFERROR(BP11-BP11*BU67*(1-INDEX([1]Tables!$EA$4:$EE$60,MATCH([1]Tables!$C$22&$BX11,[1]Tables!$EA$4:$EA$60,0),[1]Tables!$EE$1))*(1-DL11)/CG58, 0)} -> 0 | DG11: {=IFERROR(BQ11-BQ11*BV67*(1-INDEX([1]Tables!$EA$4:$EE$60,MATCH([1]Tables!$C$22&$BX11,[1]Tables!$EA$4:$EA$60,0),[1]Tables!$EE$1))*(1-DM11)/CH58, 0)} -> 0 | DI11: {=IFERROR(((SUMPRODUCT((rng_out_mail_ind = $B11) * (rng_out_ds = $C11) * (rng_out_sel_sp_ind = $D11) * (rng_out_sel_excl_ind = $E11) * (rng_out_base_post_yr1*rng_out_340B)) + IF([1]Tables!$C$16=[1]Tables!$CF$4, SUMPRODUCT((rng_out_mail_ind = $B11) * (rng_out_ds = $C11) * (rng_out_sel_sp_ind = $D11) * (rng_out_sel_excl_ind = $F11) * (rng_out_base_post_yr1*rng_out_340B)), 0))/[1]Tables!$AT$4)/AQ11, 0)} -> 0 | DJ11: {=IFERROR(((SUMPRODUCT((rng_out_mail_ind = $B11) * (rng_out_ds = $C11) * (rng_out_sel_sp_ind = $D11) * (rng_out_sel_excl_ind = $E11) * (rng_out_base_post_yr2*rng_out_340B)) + IF([1]Tables!$C$16=[1]Tables!$CF$4, SUMPRODUCT((rng_out_mail_ind = $B11) * (rng_out_ds = $C11) * (rng_out_sel_sp_ind = $D11) * (rng_out_sel_excl_ind = $F11) * (rng_out_base_post_yr2*rng_out_340B)), 0))/[1]Tables!$AT$4)/AR11, 0)} -> 0 | DK11: {=IFERROR(((SUMPRODUCT((rng_out_mail_ind = $B11) * (rng_out_ds = $C11) * (rng_out_sel_sp_ind = $D11) * (rng_out_sel_excl_ind = $E11) * (rng_out_base_post_yr3*rng_out_340B)) + IF([1]Tables!$C$16=[1]Tables!$CF$4, SUMPRODUCT((rng_out_mail_ind = $B11) * (rng_out_ds = $C11) * (rng_out_sel_sp_ind = $D11) * (rng_out_sel_excl_ind = $F11) * (rng_out_base_post_yr3*rng_out_340B)), 0))/[1]Tables!$AT$4)/AS11, 0)} -> 0 | DL11: {=IFERROR(((SUMPRODUCT((rng_out_mail_ind = $B11) * (rng_out_ds = $C11) * (rng_out_sel_sp_ind = $D11) * (rng_out_sel_excl_ind = $E11) * (rng_out_base_post_yr4*rng_out_340B)) + IF([1]Tables!$C$16=[1]Tables!$CF$4, SUMPRODUCT((rng_out_mail_ind = $B11) * (rng_out_ds = $C11) * (rng_out_sel_sp_ind = $D11) * (rng_out_sel_excl_ind = $F11) * (rng_out_base_post_yr4*rng_out_340B)), 0))/[1]Tables!$AT$4)/AT11, 0)} -> 0 | DM11: {=IFERROR(((SUMPRODUCT((rng_out_mail_ind = $B11) * (rng_out_ds = $C11) * (rng_out_sel_sp_ind = $D11) * (rng_out_sel_excl_ind = $E11) * (rng_out_base_post_yr5*rng_out_340B)) + IF([1]Tables!$C$16=[1]Tables!$CF$4, SUMPRODUCT((rng_out_mail_ind = $B11) * (rng_out_ds = $C11) * (rng_out_sel_sp_ind = $D11) * (rng_out_sel_excl_ind = $F11) * (rng_out_base_post_yr5*rng_out_340B)), 0))/[1]Tables!$AT$4)/AU11, 0)} -> 0
B12: R | C12: 90 | D12: N | E12: N | F12: Y | H12: Retail 90 | I12: {=SUMIFS(INDIRECT('[1]RA Output'!BP$1), rng_out_mail_ind, $B12, rng_out_ds, $C12, rng_out_sel_sp_ind, $D12, rng_out_sel_excl_ind,$E12) + SUMIFS(INDIRECT('[1]RA Output'!BP$1), rng_out_mail_ind, $B12, rng_out_ds, $C12, rng_out_sel_sp_ind, $D12, rng_out_sel_excl_ind,$F12, rng_out_sel_excl_yr_ind, ">0", rng_out_sel_excl_ind,$F12) + IF([1]Tables!$C$16=[1]Tables!$CF$4, SUMIFS(INDIRECT('[1]RA Output'!BP$1), rng_out_mail_ind, $B12, rng_out_ds, $C12, rng_out_sel_sp_ind, $D12, rng_out_sel_excl_ind,$F12,rng_out_sel_excl_yr_ind, ""), 0)} -> #REF! | J12: {=SUMIFS(INDIRECT('[1]RA Output'!BQ$1), rng_out_mail_ind, $B12, rng_out_ds, $C12, rng_out_sel_sp_ind, $D12, rng_out_sel_excl_ind,$E12) + SUMIFS(INDIRECT('[1]RA Output'!BQ$1), rng_out_mail_ind, $B12, rng_out_ds, $C12, rng_out_sel_sp_ind, $D12, rng_out_sel_excl_ind,$F12, rng_out_sel_excl_yr_ind, ">0", rng_out_sel_excl_ind,$F12) + IF([1]Tables!$C$16=[1]Tables!$CF$4, SUMIFS(INDIRECT('[1]RA Output'!BQ$1), rng_out_mail_ind, $B12, rng_out_ds, $C12, rng_out_sel_sp_ind, $D12, rng_out_sel_excl_ind,$F12,rng_out_sel_excl_yr_ind, ""), 0)} -> #REF! | K12: {=SUMIFS(INDIRECT('[1]RA Output'!BR$1), rng_out_mail_ind, $B12, rng_out_ds, $C12, rng_out_sel_sp_ind, $D12, rng_out_sel_excl_ind,$E12) + SUMIFS(INDIRECT('[1]RA Output'!BR$1), rng_out_mail_ind, $B12, rng_out_ds, $C12, rng_out_sel_sp_ind, $D12, rng_out_sel_excl_ind,$F12, rng_out_sel_excl_yr_ind, ">0", rng_out_sel_excl_ind,$F12) + IF([1]Tables!$C$16=[1]Tables!$CF$4, SUMIFS(INDIRECT('[1]RA Output'!BR$1), rng_out_mail_ind, $B12, rng_out_ds, $C12, rng_out_sel_sp_ind, $D12, rng_out_sel_excl_ind,$F12,rng_out_sel_excl_yr_ind, ""), 0)} -> #REF! | L12: {=SUMIFS(INDIRECT('[1]RA Output'!BS$1), rng_out_mail_ind, $B12, rng_out_ds, $C12, rng_out_sel_sp_ind, $D12, rng_out_sel_excl_ind,$E12) + SUMIFS(INDIRECT('[1]RA Output'!BS$1), rng_out_mail_ind, $B12, rng_out_ds, $C12, rng_out_sel_sp_ind, $D12, rng_out_sel_excl_ind,$F12, rng_out_sel_excl_yr_ind, ">0", rng_out_sel_excl_ind,$F12) + IF([1]Tables!$C$16=[1]Tables!$CF$4, SUMIFS(INDIRECT('[1]RA Output'!BS$1), rng_out_mail_ind, $B12, rng_out_ds, $C12, rng_out_sel_sp_ind, $D12, rng_out_sel_excl_ind,$F12,rng_out_sel_excl_yr_ind, ""), 0)} -> #REF! | M12: {=SUMIFS(INDIRECT('[1]RA Output'!BT$1), rng_out_mail_ind, $B12, rng_out_ds, $C12, rng_out_sel_sp_ind, $D12, rng_out_sel_excl_ind,$E12) + SUMIFS(INDIRECT('[1]RA Output'!BT$1), rng_out_mail_ind, $B12, rng_out_ds, $C12, rng_out_sel_sp_ind, $D12, rng_out_sel_excl_ind,$F12, rng_out_sel_excl_yr_ind, ">0", rng_out_sel_excl_ind,$F12) + IF([1]Tables!$C$16=[1]Tables!$CF$4, SUMIFS(INDIRECT('[1]RA Output'!BT$1), rng_out_mail_ind, $B12, rng_out_ds, $C12, rng_out_sel_sp_ind, $D12, rng_out_sel_excl_ind,$F12,rng_out_sel_excl_yr_ind, ""), 0)} -> #REF! | N12: =IFERROR(I12/N$59, 0) -> 0 | O12: =IFERROR(J12/O$59, 0) -> 0 | P12: =IFERROR(K12/P$59, 0) -> 0 | Q12: =IFERROR(L12/Q$59, 0) -> 0 | R12: =IFERROR(M12/R$59, 0) -> 0 | S12: =IFERROR(I12/S$59, 0) -> 0 | T12: =IFERROR(J12/T$59, 0) -> 0 | U12: =IFERROR(K12/U$59, 0) -> 0 | V12: =IFERROR(L12/V$59, 0) -> 0 | W12: =IFERROR(M12/W$59, 0) -> 0 | Y12: Retail 90 | Z12: =IFERROR(I12/[1]Tables!$AT$4,0) -> 0 | AA12: =IFERROR(J12/[1]Tables!$AT$4,0) -> 0 | AB12: =IFERROR(K12/[1]Tables!$AT$4,0) -> 0 | AC12: =IFERROR(L12/[1]Tables!$AT$4,0) -> 0 | AD12: =IFERROR(M12/[1]Tables!$AT$4,0) -> 0 | AE12: =IFERROR(N12/[1]Tables!$AT$4, 0) -> 0 | AF12: =IFERROR(O12/[1]Tables!$AT$4, 0) -> 0 | AG12: =IFERROR(P12/[1]Tables!$AT$4, 0) -> 0 | AH12: =IFERROR(Q12/[1]Tables!$AT$4, 0) -> 0 | AI12: =IFERROR(R12/[1]Tables!$AT$4, 0) -> 0 | AJ12: =IFERROR(S12/[1]Tables!$AT$4,0) -> 0 | AK12: =IFERROR(T12/[1]Tables!$AT$4,0) -> 0 | AL12: =IFERROR(U12/[1]Tables!$AT$4,0) -> 0 | AM12: =IFERROR(V12/[1]Tables!$AT$4,0) -> 0 | AN12: =IFERROR(W12/[1]Tables!$AT$4,0) -> 0 | AP12: Retail 90 | AQ12: {=(SUMIFS(INDIRECT('[1]RA Output'!CP$1), rng_out_mail_ind, $B12, rng_out_ds, $C12, rng_out_sel_sp_ind, $D12, rng_out_sel_excl_ind,$E12) + SUMIFS(INDIRECT('[1]RA Output'!CP$1), rng_out_mail_ind, $B12, rng_out_ds, $C12, rng_out_sel_sp_ind, $D12, rng_out_sel_excl_ind,$F12, rng_out_sel_excl_yr_ind, ">0", rng_out_sel_excl_ind,$F12) + IF([1]Tables!$C$16=[1]Tables!$CF$4, SUMIFS(INDIRECT('[1]RA Output'!CP$1), rng_out_mail_ind, $B12, rng_out_ds, $C12, rng_out_sel_sp_ind, $D12, rng_out_sel_excl_ind,$F12,rng_out_sel_excl_yr_ind, ""), 0))/[1]Tables!$AT$4} -> #REF! | AR12: {=(SUMIFS(INDIRECT('[1]RA Output'!CQ$1), rng_out_mail_ind, $B12, rng_out_ds, $C12, rng_out_sel_sp_ind, $D12, rng_out_sel_excl_ind,$E12) + SUMIFS(INDIRECT('[1]RA Output'!CQ$1), rng_out_mail_ind, $B12, rng_out_ds, $C12, rng_out_sel_sp_ind, $D12, rng_out_sel_excl_ind,$F12, rng_out_sel_excl_yr_ind, ">0", rng_out_sel_excl_ind,$F12) + IF([1]Tables!$C$16=[1]Tables!$CF$4, SUMIFS(INDIRECT('[1]RA Output'!CQ$1), rng_out_mail_ind, $B12, rng_out_ds, $C12, rng_out_sel_sp_ind, $D12, rng_out_sel_excl_ind,$F12,rng_out_sel_excl_yr_ind, ""), 0))/[1]Tables!$AT$4} -> #REF! | AS12: {=(SUMIFS(INDIRECT('[1]RA Output'!CR$1), rng_out_mail_ind, $B12, rng_out_ds, $C12, rng_out_sel_sp_ind, $D12, rng_out_sel_excl_ind,$E12) + SUMIFS(INDIRECT('[1]RA Output'!CR$1), rng_out_mail_ind, $B12, rng_out_ds, $C12, rng_out_sel_sp_ind, $D12, rng_out_sel_excl_ind,$F12, rng_out_sel_excl_yr_ind, ">0", rng_out_sel_excl_ind,$F12) + IF([1]Tables!$C$16=[1]Tables!$CF$4, SUMIFS(INDIRECT('[1]RA Output'!CR$1), rng_out_mail_ind, $B12, rng_out_ds, $C12, rng_out_sel_sp_ind, $D12, rng_out_sel_excl_ind,$F12,rng_out_sel_excl_yr_ind, ""), 0))/[1]Tables!$AT$4} -> #REF! | AT12: {=(SUMIFS(INDIRECT('[1]RA Output'!CS$1), rng_out_mail_ind, $B12, rng_out_ds, $C12, rng_out_sel_sp_ind, $D12, rng_out_sel_excl_ind,$E12) + SUMIFS(INDIRECT('[1]RA Output'!CS$1), rng_out_mail_ind, $B12, rng_out_ds, $C12, rng_out_sel_sp_ind, $D12, rng_out_sel_excl_ind,$F12, rng_out_sel_excl_yr_ind, ">0", rng_out_sel_excl_ind,$F12) + IF([1]Tables!$C$16=[1]Tables!$CF$4, SUMIFS(INDIRECT('[1]RA Output'!CS$1), rng_out_mail_ind, $B12, rng_out_ds, $C12, rng_out_sel_sp_ind, $D12, rng_out_sel_excl_ind,$F12,rng_out_sel_excl_yr_ind, ""), 0))/[1]Tables!$AT$4} -> #REF! | AU12: {=(SUMIFS(INDIRECT('[1]RA Output'!CT$1), rng_out_mail_ind, $B12, rng_out_ds, $C12, rng_out_sel_sp_ind, $D12, rng_out_sel_excl_ind,$E12) + SUMIFS(INDIRECT('[1]RA Output'!CT$1), rng_out_mail_ind, $B12, rng_out_ds, $C12, rng_out_sel_sp_ind, $D12, rng_out_sel_excl_ind,$F12, rng_out_sel_excl_yr_ind, ">0", rng_out_sel_excl_ind,$F12) + IF([1]Tables!$C$16=[1]Tables!$CF$4, SUMIFS(INDIRECT('[1]RA Output'!CT$1), rng_out_mail_ind, $B12, rng_out_ds, $C12, rng_out_sel_sp_ind, $D12, rng_out_sel_excl_ind,$F12,rng_out_sel_excl_yr_ind, ""), 0))/[1]Tables!$AT$4} -> #REF! | AV12: =IFERROR(AQ12/AV$59, 0) -> 0 | AW12: =IFERROR(AR12/AW$59, 0) -> 0 | AX12: =IFERROR(AS12/AX$59, 0) -> 0 | AY12: =IFERROR(AT12/AY$59, 0) -> 0 | AZ12: =IFERROR(AU12/AZ$59, 0) -> 0 | BA12: =IFERROR(AQ12/BA$59, 0) -> 0 | BB12: =IFERROR(AR12/BB$59, 0) -> 0 | BC12: =IFERROR(AS12/BC$59, 0) -> 0 | BD12: =IFERROR(AT12/BD$59, 0) -> 0 | BE12: =IFERROR(AU12/BE$59, 0) -> 0 | BG12: Retail 90 | BH12: {=(SUMIFS(INDIRECT('[1]RA Output'!DP$1), rng_out_mail_ind, $B12, rng_out_ds, $C12, rng_out_sel_sp_ind, $D12, rng_out_sel_excl_ind,$E12) + SUMIFS(INDIRECT('[1]RA Output'!DP$1), rng_out_mail_ind, $B12, rng_out_ds, $C12, rng_out_sel_sp_ind, $D12, rng_out_sel_excl_ind,$F12, rng_out_sel_excl_yr_ind, ">0") + IF([1]Tables!$C$16=[1]Tables!$CF$4, SUMIFS(INDIRECT('[1]RA Output'!DP$1), rng_out_mail_ind, $B12, rng_out_ds, $C12, rng_out_sel_sp_ind, $D12, rng_out_sel_excl_ind,$F12,rng_out_sel_excl_yr_ind, ""), 0))/[1]Tables!$AT$4} -> #REF! | BI12: {=(SUMIFS(INDIRECT('[1]RA Output'!DQ$1), rng_out_mail_ind, $B12, rng_out_ds, $C12, rng_out_sel_sp_ind, $D12, rng_out_sel_excl_ind,$E12) + SUMIFS(INDIRECT('[1]RA Output'!DQ$1), rng_out_mail_ind, $B12, rng_out_ds, $C12, rng_out_sel_sp_ind, $D12, rng_out_sel_excl_ind,$F12, rng_out_sel_excl_yr_ind, ">0") + IF([1]Tables!$C$16=[1]Tables!$CF$4, SUMIFS(INDIRECT('[1]RA Output'!DQ$1), rng_out_mail_ind, $B12, rng_out_ds, $C12, rng_out_sel_sp_ind, $D12, rng_out_sel_excl_ind,$F12,rng_out_sel_excl_yr_ind, ""), 0))/[1]Tables!$AT$4} -> #REF! | BJ12: {=(SUMIFS(INDIRECT('[1]RA Output'!DR$1), rng_out_mail_ind, $B12, rng_out_ds, $C12, rng_out_sel_sp_ind, $D12, rng_out_sel_excl_ind,$E12) + SUMIFS(INDIRECT('[1]RA Output'!DR$1), rng_out_mail_ind, $B12, rng_out_ds, $C12, rng_out_sel_sp_ind, $D12, rng_out_sel_excl_ind,$F12, rng_out_sel_excl_yr_ind, ">0") + IF([1]Tables!$C$16=[1]Tables!$CF$4, SUMIFS(INDIRECT('[1]RA Output'!DR$1), rng_out_mail_ind, $B12, rng_out_ds, $C12, rng_out_sel_sp_ind, $D12, rng_out_sel_excl_ind,$F12,rng_out_sel_excl_yr_ind, ""), 0))/[1]Tables!$AT$4} -> #REF! | BK12: {=(SUMIFS(INDIRECT('[1]RA Output'!DS$1), rng_out_mail_ind, $B12, rng_out_ds, $C12, rng_out_sel_sp_ind, $D12, rng_out_sel_excl_ind,$E12) + SUMIFS(INDIRECT('[1]RA Output'!DS$1), rng_out_mail_ind, $B12, rng_out_ds, $C12, rng_out_sel_sp_ind, $D12, rng_out_sel_excl_ind,$F12, rng_out_sel_excl_yr_ind, ">0") + IF([1]Tables!$C$16=[1]Tables!$CF$4, SUMIFS(INDIRECT('[1]RA Output'!DS$1), rng_out_mail_ind, $B12, rng_out_ds, $C12, rng_out_sel_sp_ind, $D12, rng_out_sel_excl_ind,$F12,rng_out_sel_excl_yr_ind, ""), 0))/[1]Tables!$AT$4} -> #REF! | BL12: {=(SUMIFS(INDIRECT('[1]RA Output'!DT$1), rng_out_mail_ind, $B12, rng_out_ds, $C12, rng_out_sel_sp_ind, $D12, rng_out_sel_excl_ind,$E12) + SUMIFS(INDIRECT('[1]RA Output'!DT$1), rng_out_mail_ind, $B12, rng_out_ds, $C12, rng_out_sel_sp_ind, $D12, rng_out_sel_excl_ind,$F12, rng_out_sel_excl_yr_ind, ">0") + IF([1]Tables!$C$16=[1]Tables!$CF$4, SUMIFS(INDIRECT('[1]RA Output'!DT$1), rng_out_mail_ind, $B12, rng_out_ds, $C12, rng_out_sel_sp_ind, $D12, rng_out_sel_excl_ind,$F12,rng_out_sel_excl_yr_ind, ""), 0))/[1]Tables!$AT$4} -> #REF! | BM12: =IFERROR(BH12/BM$59, 0) -> 0 | BN12: =IFERROR(BI12/BN$59, 0) -> 0 | BO12: =IFERROR(BJ12/BO$59, 0) -> 0 | BP12: =IFERROR(BK12/BP$59, 0) -> 0 | BQ12: =IFERROR(BL12/BQ$59, 0) -> 0 | BR12: =IFERROR(BH12/BR$59, 0) -> 0 | BS12: =IFERROR(BI12/BS$59, 0) -> 0 | BT12: =IFERROR(BJ12/BT$59, 0) -> 0 | BU12: =IFERROR(BK12/BU$59, 0) -> 0 | BV12: =IFERROR(BL12/BV$59, 0) -> 0 | BX12: Retail 90 | BY12: =CD12*CD59 -> #VALUE! | BZ12: =CE12*CE59 -> #VALUE! | CA12: =CF12*CF59 -> #VALUE! | CB12: =CG12*CG59 -> #VALUE! | CC12: =CH12*CH59 -> #VALUE! | CD12: =BM12-DC12 -> 0 | CE12: =BN12-DD12 -> 0 | CF12: =BO12-DE12 -> 0 | CG12: =BP12-DF12 -> 0 | CH12: =BQ12-DG12 -> 0 | CI12: =IFERROR(BY12/CI59, 0) -> 0 | CJ12: =IFERROR(BZ12/CJ59, 0) -> 0 | CK12: =IFERROR(CA12/CK59, 0) -> 0 | CL12: =IFERROR(CB12/CL59, 0) -> 0 | CM12: =IFERROR(CC12/CM59, 0) -> 0 | DC12: {=IFERROR(BM12-BM12*BR68*(1-INDEX([1]Tables!$EA$4:$EE$60,MATCH([1]Tables!$C$22&$BX12,[1]Tables!$EA$4:$EA$60,0),[1]Tables!$EE$1))*(1-DI12)/CD59, 0)} -> 0 | DD12: {=IFERROR(BN12-BN12*BS68*(1-INDEX([1]Tables!$EA$4:$EE$60,MATCH([1]Tables!$C$22&$BX12,[1]Tables!$EA$4:$EA$60,0),[1]Tables!$EE$1))*(1-DJ12)/CE59, 0)} -> 0 | DE12: {=IFERROR(BO12-BO12*BT68*(1-INDEX([1]Tables!$EA$4:$EE$60,MATCH([1]Tables!$C$22&$BX12,[1]Tables!$EA$4:$EA$60,0),[1]Tables!$EE$1))*(1-DK12)/CF59, 0)} -> 0 | DF12: {=IFERROR(BP12-BP12*BU68*(1-INDEX([1]Tables!$EA$4:$EE$60,MATCH([1]Tables!$C$22&$BX12,[1]Tables!$EA$4:$EA$60,0),[1]Tables!$EE$1))*(1-DL12)/CG59, 0)} -> 0 | DG12: {=IFERROR(BQ12-BQ12*BV68*(1-INDEX([1]Tables!$EA$4:$EE$60,MATCH([1]Tables!$C$22&$BX12,[1]Tables!$EA$4:$EA$60,0),[1]Tables!$EE$1))*(1-DM12)/CH59, 0)} -> 0 | DI12: {=IFERROR(((SUMPRODUCT((rng_out_mail_ind = $B12) * (rng_out_ds = $C12) * (rng_out_sel_sp_ind = $D12) * (rng_out_sel_excl_ind = $E12) * (rng_out_base_post_yr1*rng_out_340B)) + IF([1]Tables!$C$16=[1]Tables!$CF$4, SUMPRODUCT((rng_out_mail_ind = $B12) * (rng_out_ds = $C12) * (rng_out_sel_sp_ind = $D12) * (rng_out_sel_excl_ind = $F12) * (rng_out_base_post_yr1*rng_out_340B)), 0))/[1]Tables!$AT$4)/AQ12, 0)} -> 0 | DJ12: {=IFERROR(((SUMPRODUCT((rng_out_mail_ind = $B12) * (rng_out_ds = $C12) * (rng_out_sel_sp_ind = $D12) * (rng_out_sel_excl_ind = $E12) * (rng_out_base_post_yr2*rng_out_340B)) + IF([1]Tables!$C$16=[1]Tables!$CF$4, SUMPRODUCT((rng_out_mail_ind = $B12) * (rng_out_ds = $C12) * (rng_out_sel_sp_ind = $D12) * (rng_out_sel_excl_ind = $F12) * (rng_out_base_post_yr2*rng_out_340B)), 0))/[1]Tables!$AT$4)/AR12, 0)} -> 0 | DK12: {=IFERROR(((SUMPRODUCT((rng_out_mail_ind = $B12) * (rng_out_ds = $C12) * (rng_out_sel_sp_ind = $D12) * (rng_out_sel_excl_ind = $E12) * (rng_out_base_post_yr3*rng_out_340B)) + IF([1]Tables!$C$16=[1]Tables!$CF$4, SUMPRODUCT((rng_out_mail_ind = $B12) * (rng_out_ds = $C12) * (rng_out_sel_sp_ind = $D12) * (rng_out_sel_excl_ind = $F12) * (rng_out_base_post_yr3*rng_out_340B)), 0))/[1]Tables!$AT$4)/AS12, 0)} -> 0 | DL12: {=IFERROR(((SUMPRODUCT((rng_out_mail_ind = $B12) * (rng_out_ds = $C12) * (rng_out_sel_sp_ind = $D12) * (rng_out_sel_excl_ind = $E12) * (rng_out_base_post_yr4*rng_out_340B)) + IF([1]Tables!$C$16=[1]Tables!$CF$4, SUMPRODUCT((rng_out_mail_ind = $B12) * (rng_out_ds = $C12) * (rng_out_sel_sp_ind = $D12) * (rng_out_sel_excl_ind = $F12) * (rng_out_base_post_yr4*rng_out_340B)), 0))/[1]Tables!$AT$4)/AT12, 0)} -> 0 | DM12: {=IFERROR(((SUMPRODUCT((rng_out_mail_ind = $B12) * (rng_out_ds = $C12) * (rng_out_sel_sp_ind = $D12) * (rng_out_sel_excl_ind = $E12) * (rng_out_base_post_yr5*rng_out_340B)) + IF([1]Tables!$C$16=[1]Tables!$CF$4, SUMPRODUCT((rng_out_mail_ind = $B12) * (rng_out_ds = $C12) * (rng_out_sel_sp_ind = $D12) * (rng_out_sel_excl_ind = $F12) * (rng_out_base_post_yr5*rng_out_340B)), 0))/[1]Tables!$AT$4)/AU12, 0)} -> 0
B13: M | D13: N | E13: N | F13: Y | H13: Mail | I13: {=SUMIFS(INDIRECT('[1]RA Output'!BP$1), rng_out_mail_ind, $B13, rng_out_sel_sp_ind, $D13, rng_out_sel_excl_ind,$E13) + SUMIFS(INDIRECT('[1]RA Output'!BP$1), rng_out_mail_ind, $B13, rng_out_sel_sp_ind, $D13, rng_out_sel_excl_ind,$F13, rng_out_sel_excl_yr_ind, ">0") + IF([1]Tables!$C$16=[1]Tables!$CF$4, SUMIFS(INDIRECT('[1]RA Output'!BP$1), rng_out_mail_ind, $B13, rng_out_sel_sp_ind, $D13, rng_out_sel_excl_ind,$F13,rng_out_sel_excl_yr_ind, ""), 0)} -> #REF! | J13: {=SUMIFS(INDIRECT('[1]RA Output'!BQ$1), rng_out_mail_ind, $B13, rng_out_sel_sp_ind, $D13, rng_out_sel_excl_ind,$E13) + SUMIFS(INDIRECT('[1]RA Output'!BQ$1), rng_out_mail_ind, $B13, rng_out_sel_sp_ind, $D13, rng_out_sel_excl_ind,$F13, rng_out_sel_excl_yr_ind, ">0") + IF([1]Tables!$C$16=[1]Tables!$CF$4, SUMIFS(INDIRECT('[1]RA Output'!BQ$1), rng_out_mail_ind, $B13, rng_out_sel_sp_ind, $D13, rng_out_sel_excl_ind,$F13,rng_out_sel_excl_yr_ind, ""), 0)} -> #REF! | K13: {=SUMIFS(INDIRECT('[1]RA Output'!BR$1), rng_out_mail_ind, $B13, rng_out_sel_sp_ind, $D13, rng_out_sel_excl_ind,$E13) + SUMIFS(INDIRECT('[1]RA Output'!BR$1), rng_out_mail_ind, $B13, rng_out_sel_sp_ind, $D13, rng_out_sel_excl_ind,$F13, rng_out_sel_excl_yr_ind, ">0") + IF([1]Tables!$C$16=[1]Tables!$CF$4, SUMIFS(INDIRECT('[1]RA Output'!BR$1), rng_out_mail_ind, $B13, rng_out_sel_sp_ind, $D13, rng_out_sel_excl_ind,$F13,rng_out_sel_excl_yr_ind, ""), 0)} -> #REF! | L13: {=SUMIFS(INDIRECT('[1]RA Output'!BS$1), rng_out_mail_ind, $B13, rng_out_sel_sp_ind, $D13, rng_out_sel_excl_ind,$E13) + SUMIFS(INDIRECT('[1]RA Output'!BS$1), rng_out_mail_ind, $B13, rng_out_sel_sp_ind, $D13, rng_out_sel_excl_ind,$F13, rng_out_sel_excl_yr_ind, ">0") + IF([1]Tables!$C$16=[1]Tables!$CF$4, SUMIFS(INDIRECT('[1]RA Output'!BS$1), rng_out_mail_ind, $B13, rng_out_sel_sp_ind, $D13, rng_out_sel_excl_ind,$F13,rng_out_sel_excl_yr_ind, ""), 0)} -> #REF! | M13: {=SUMIFS(INDIRECT('[1]RA Output'!BT$1), rng_out_mail_ind, $B13, rng_out_sel_sp_ind, $D13, rng_out_sel_excl_ind,$E13) + SUMIFS(INDIRECT('[1]RA Output'!BT$1), rng_out_mail_ind, $B13, rng_out_sel_sp_ind, $D13, rng_out_sel_excl_ind,$F13, rng_out_sel_excl_yr_ind, ">0") + IF([1]Tables!$C$16=[1]Tables!$CF$4, SUMIFS(INDIRECT('[1]RA Output'!BT$1), rng_out_mail_ind, $B13, rng_out_sel_sp_ind, $D13, rng_out_sel_excl_ind,$F13,rng_out_sel_excl_yr_ind, ""), 0)} -> #REF! | N13: =IFERROR(I13/N$60, 0) -> 0 | O13: =IFERROR(J13/O$60, 0) -> 0 | P13: =IFERROR(K13/P$60, 0) -> 0 | Q13: =IFERROR(L13/Q$60, 0) -> 0 | R13: =IFERROR(M13/R$60, 0) -> 0 | S13: =IFERROR(I13/S$60, 0) -> 0 | T13: =IFERROR(J13/T$60, 0) -> 0 | U13: =IFERROR(K13/U$60, 0) -> 0 | V13: =IFERROR(L13/V$60, 0) -> 0 | W13: =IFERROR(M13/W$60, 0) -> 0 | Y13: Mail | Z13: =IFERROR(I13/[1]Tables!$AT$4,0) -> 0 | AA13: =IFERROR(J13/[1]Tables!$AT$4,0) -> 0 | AB13: =IFERROR(K13/[1]Tables!$AT$4,0) -> 0 | AC13: =IFERROR(L13/[1]Tables!$AT$4,0) -> 0 | AD13: =IFERROR(M13/[1]Tables!$AT$4,0) -> 0 | AE13: =IFERROR(N13/[1]Tables!$AT$4, 0) -> 0 | AF13: =IFERROR(O13/[1]Tables!$AT$4, 0) -> 0 | AG13: =IFERROR(P13/[1]Tables!$AT$4, 0) -> 0 | AH13: =IFERROR(Q13/[1]Tables!$AT$4, 0) -> 0 | AI13: =IFERROR(R13/[1]Tables!$AT$4, 0) -> 0 | AJ13: =IFERROR(S13/[1]Tables!$AT$4,0) -> 0 | AK13: =IFERROR(T13/[1]Tables!$AT$4,0) -> 0 | AL13: =IFERROR(U13/[1]Tables!$AT$4,0) -> 0 | AM13: =IFERROR(V13/[1]Tables!$AT$4,0) -> 0 | AN13: =IFERROR(W13/[1]Tables!$AT$4,0) -> 0 | AP13: Mail | AQ13: {=(SUMIFS(INDIRECT('[1]RA Output'!CP$1), rng_out_mail_ind, $B13, rng_out_sel_sp_ind, $D13, rng_out_sel_excl_ind,$E13) + SUMIFS(INDIRECT('[1]RA Output'!CP$1), rng_out_mail_ind, $B13, rng_out_sel_sp_ind, $D13, rng_out_sel_excl_ind,$F13, rng_out_sel_excl_yr_ind, ">0") + IF([1]Tables!$C$16=[1]Tables!$CF$4, SUMIFS(INDIRECT('[1]RA Output'!CP$1), rng_out_mail_ind, $B13, rng_out_sel_sp_ind, $D13, rng_out_sel_excl_ind,$F13,rng_out_sel_excl_yr_ind, ""), 0))/[1]Tables!$AT$4} -> #REF! | AR13: {=(SUMIFS(INDIRECT('[1]RA Output'!CQ$1), rng_out_mail_ind, $B13, rng_out_sel_sp_ind, $D13, rng_out_sel_excl_ind,$E13) + SUMIFS(INDIRECT('[1]RA Output'!CQ$1), rng_out_mail_ind, $B13, rng_out_sel_sp_ind, $D13, rng_out_sel_excl_ind,$F13, rng_out_sel_excl_yr_ind, ">0") + IF([1]Tables!$C$16=[1]Tables!$CF$4, SUMIFS(INDIRECT('[1]RA Output'!CQ$1), rng_out_mail_ind, $B13, rng_out_sel_sp_ind, $D13, rng_out_sel_excl_ind,$F13,rng_out_sel_excl_yr_ind, ""), 0))/[1]Tables!$AT$4} -> #REF! | AS13: {=(SUMIFS(INDIRECT('[1]RA Output'!CR$1), rng_out_mail_ind, $B13, rng_out_sel_sp_ind, $D13, rng_out_sel_excl_ind,$E13) + SUMIFS(INDIRECT('[1]RA Output'!CR$1), rng_out_mail_ind, $B13, rng_out_sel_sp_ind, $D13, rng_out_sel_excl_ind,$F13, rng_out_sel_excl_yr_ind, ">0") + IF([1]Tables!$C$16=[1]Tables!$CF$4, SUMIFS(INDIRECT('[1]RA Output'!CR$1), rng_out_mail_ind, $B13, rng_out_sel_sp_ind, $D13, rng_out_sel_excl_ind,$F13,rng_out_sel_excl_yr_ind, ""), 0))/[1]Tables!$AT$4} -> #REF! | AT13: {=(SUMIFS(INDIRECT('[1]RA Output'!CS$1), rng_out_mail_ind, $B13, rng_out_sel_sp_ind, $D13, rng_out_sel_excl_ind,$E13) + SUMIFS(INDIRECT('[1]RA Output'!CS$1), rng_out_mail_ind, $B13, rng_out_sel_sp_ind, $D13, rng_out_sel_excl_ind,$F13, rng_out_sel_excl_yr_ind, ">0") + IF([1]Tables!$C$16=[1]Tables!$CF$4, SUMIFS(INDIRECT('[1]RA Output'!CS$1), rng_out_mail_ind, $B13, rng_out_sel_sp_ind, $D13, rng_out_sel_excl_ind,$F13,rng_out_sel_excl_yr_ind, ""), 0))/[1]Tables!$AT$4} -> #REF! | AU13: {=(SUMIFS(INDIRECT('[1]RA Output'!CT$1), rng_out_mail_ind, $B13, rng_out_sel_sp_ind, $D13, rng_out_sel_excl_ind,$E13) + SUMIFS(INDIRECT('[1]RA Output'!CT$1), rng_out_mail_ind, $B13, rng_out_sel_sp_ind, $D13, rng_out_sel_excl_ind,$F13, rng_out_sel_excl_yr_ind, ">0") + IF([1]Tables!$C$16=[1]Tables!$CF$4, SUMIFS(INDIRECT('[1]RA Output'!CT$1), rng_out_mail_ind, $B13, rng_out_sel_sp_ind, $D13, rng_out_sel_excl_ind,$F13,rng_out_sel_excl_yr_ind, ""), 0))/[1]Tables!$AT$4} -> #REF! | AV13: =IFERROR(AQ13/AV$60, 0) -> 0 | AW13: =IFERROR(AR13/AW$60, 0) -> 0 | AX13: =IFERROR(AS13/AX$60, 0) -> 0 | AY13: =IFERROR(AT13/AY$60, 0) -> 0 | AZ13: =IFERROR(AU13/AZ$60, 0) -> 0 | BA13: =IFERROR(AQ13/BA$60, 0) -> 0 | BB13: =IFERROR(AR13/BB$60, 0) -> 0 | BC13: =IFERROR(AS13/BC$60, 0) -> 0 | BD13: =IFERROR(AT13/BD$60, 0) -> 0 | BE13: =IFERROR(AU13/BE$60, 0) -> 0 | BG13: Mail | BH13: {=(SUMIFS(INDIRECT('[1]RA Output'!DP$1), rng_out_mail_ind, $B13, rng_out_sel_sp_ind, $D13, rng_out_sel_excl_ind,$E13) + SUMIFS(INDIRECT('[1]RA Output'!DP$1), rng_out_mail_ind, $B13, rng_out_sel_sp_ind, $D13, rng_out_sel_excl_ind,$F13, rng_out_sel_excl_yr_ind, ">0") + IF([1]Tables!$C$16=[1]Tables!$CF$4, SUMIFS(INDIRECT('[1]RA Output'!DP$1), rng_out_mail_ind, $B13, rng_out_sel_sp_ind, $D13, rng_out_sel_excl_ind,$F13,rng_out_sel_excl_yr_ind, ""), 0))/[1]Tables!$AT$4} -> #REF! | BI13: {=(SUMIFS(INDIRECT('[1]RA Output'!DQ$1), rng_out_mail_ind, $B13, rng_out_sel_sp_ind, $D13, rng_out_sel_excl_ind,$E13) + SUMIFS(INDIRECT('[1]RA Output'!DQ$1), rng_out_mail_ind, $B13, rng_out_sel_sp_ind, $D13, rng_out_sel_excl_ind,$F13, rng_out_sel_excl_yr_ind, ">0") + IF([1]Tables!$C$16=[1]Tables!$CF$4, SUMIFS(INDIRECT('[1]RA Output'!DQ$1), rng_out_mail_ind, $B13, rng_out_sel_sp_ind, $D13, rng_out_sel_excl_ind,$F13,rng_out_sel_excl_yr_ind, ""), 0))/[1]Tables!$AT$4} -> #REF! | BJ13: {=(SUMIFS(INDIRECT('[1]RA Output'!DR$1), rng_out_mail_ind, $B13, rng_out_sel_sp_ind, $D13, rng_out_sel_excl_ind,$E13) + SUMIFS(INDIRECT('[1]RA Output'!DR$1), rng_out_mail_ind, $B13, rng_out_sel_sp_ind, $D13, rng_out_sel_excl_ind,$F13, rng_out_sel_excl_yr_ind, ">0") + IF([1]Tables!$C$16=[1]Tables!$CF$4, SUMIFS(INDIRECT('[1]RA Output'!DR$1), rng_out_mail_ind, $B13, rng_out_sel_sp_ind, $D13, rng_out_sel_excl_ind,$F13,rng_out_sel_excl_yr_ind, ""), 0))/[1]Tables!$AT$4} -> #REF! | BK13: {=(SUMIFS(INDIRECT('[1]RA Output'!DS$1), rng_out_mail_ind, $B13, rng_out_sel_sp_ind, $D13, rng_out_sel_excl_ind,$E13) + SUMIFS(INDIRECT('[1]RA Output'!DS$1), rng_out_mail_ind, $B13, rng_out_sel_sp_ind, $D13, rng_out_sel_excl_ind,$F13, rng_out_sel_excl_yr_ind, ">0") + IF([1]Tables!$C$16=[1]Tables!$CF$4, SUMIFS(INDIRECT('[1]RA Output'!DS$1), rng_out_mail_ind, $B13, rng_out_sel_sp_ind, $D13, rng_out_sel_excl_ind,$F13,rng_out_sel_excl_yr_ind, ""), 0))/[1]Tables!$AT$4} -> #REF! | BL13: {=(SUMIFS(INDIRECT('[1]RA Output'!DT$1), rng_out_mail_ind, $B13, rng_out_sel_sp_ind, $D13, rng_out_sel_excl_ind,$E13) + SUMIFS(INDIRECT('[1]RA Output'!DT$1), rng_out_mail_ind, $B13, rng_out_sel_sp_ind, $D13, rng_out_sel_excl_ind,$F13, rng_out_sel_excl_yr_ind, ">0") + IF([1]Tables!$C$16=[1]Tables!$CF$4, SUMIFS(INDIRECT('[1]RA Output'!DT$1), rng_out_mail_ind, $B13, rng_out_sel_sp_ind, $D13, rng_out_sel_excl_ind,$F13,rng_out_sel_excl_yr_ind, ""), 0))/[1]Tables!$AT$4} -> #REF! | BM13: =IFERROR(BH13/BM$60, 0) -> 0 | BN13: =IFERROR(BI13/BN$60, 0) -> 0 | BO13: =IFERROR(BJ13/BO$60, 0) -> 0 | BP13: =IFERROR(BK13/BP$60, 0) -> 0 | BQ13: =IFERROR(BL13/BQ$60, 0) -> 0 | BR13: =IFERROR(BH13/BR$60, 0) -> 0 | BS13: =IFERROR(BI13/BS$60, 0) -> 0 | BT13: =IFERROR(BJ13/BT$60, 0) -> 0 | BU13: =IFERROR(BK13/BU$60, 0) -> 0 | BV13: =IFERROR(BL13/BV$60, 0) -> 0 | BX13: Mail | BY13: =CD13*CD60 -> #VALUE! | BZ13: =CE13*CE60 -> #VALUE! | CA13: =CF13*CF60 -> #VALUE! | CB13: =CG13*CG60 -> #VALUE! | CC13: =CH13*CH60 -> #VALUE! | CD13: =BM13-DC13 -> 0 | CE13: =BN13-DD13 -> 0 | CF13: =BO13-DE13 -> 0 | CG13: =BP13-DF13 -> 0 | CH13: =BQ13-DG13 -> 0 | CI13: =IFERROR(BY13/CI60, 0) -> 0 | CJ13: =IFERROR(BZ13/CJ60, 0) -> 0 | CK13: =IFERROR(CA13/CK60, 0) -> 0 | CL13: =IFERROR(CB13/CL60, 0) -> 0 | CM13: =IFERROR(CC13/CM60, 0) -> 0 | DC13: {=IFERROR(BM13-BM13*BR69*(1-INDEX([1]Tables!$EA$4:$EE$60,MATCH([1]Tables!$C$22&$BX13,[1]Tables!$EA$4:$EA$60,0),[1]Tables!$EE$1))*(1-DI13)/CD60, 0)} -> 0 | DD13: {=IFERROR(BN13-BN13*BS69*(1-INDEX([1]Tables!$EA$4:$EE$60,MATCH([1]Tables!$C$22&$BX13,[1]Tables!$EA$4:$EA$60,0),[1]Tables!$EE$1))*(1-DJ13)/CE60, 0)} -> 0 | DE13: {=IFERROR(BO13-BO13*BT69*(1-INDEX([1]Tables!$EA$4:$EE$60,MATCH([1]Tables!$C$22&$BX13,[1]Tables!$EA$4:$EA$60,0),[1]Tables!$EE$1))*(1-DK13)/CF60, 0)} -> 0 | DF13: {=IFERROR(BP13-BP13*BU69*(1-INDEX([1]Tables!$EA$4:$EE$60,MATCH([1]Tables!$C$22&$BX13,[1]Tables!$EA$4:$EA$60,0),[1]Tables!$EE$1))*(1-DL13)/CG60, 0)} -> 0 | DG13: {=IFERROR(BQ13-BQ13*BV69*(1-INDEX([1]Tables!$EA$4:$EE$60,MATCH([1]Tables!$C$22&$BX13,[1]Tables!$EA$4:$EA$60,0),[1]Tables!$EE$1))*(1-DM13)/CH60, 0)} -> 0 | DI13: {=IFERROR(((SUMPRODUCT((rng_out_mail_ind = $B13) * (rng_out_sel_sp_ind = $D13) * (rng_out_sel_excl_ind = $E13) * (rng_out_base_post_yr1*rng_out_340B)) + IF([1]Tables!$C$16=[1]Tables!$CF$4, SUMPRODUCT((rng_out_mail_ind = $B13) * (rng_out_sel_sp_ind = $D13) * (rng_out_sel_excl_ind = $F13) * (rng_out_base_post_yr1*rng_out_340B)), 0))/[1]Tables!$AT$4)/AQ13, 0)} -> 0 | DJ13: {=IFERROR(((SUMPRODUCT((rng_out_mail_ind = $B13) * (rng_out_sel_sp_ind = $D13) * (rng_out_sel_excl_ind = $E13) *(rng_out_base_post_yr2*rng_out_340B)) + IF([1]Tables!$C$16=[1]Tables!$CF$4, SUMPRODUCT((rng_out_mail_ind = $B13) * (rng_out_sel_sp_ind = $D13) * (rng_out_sel_excl_ind = $F13) * (rng_out_base_post_yr2*rng_out_340B)), 0))/[1]Tables!$AT$4)/AR13, 0)} -> 0 | DK13: {=IFERROR(((SUMPRODUCT((rng_out_mail_ind = $B13) * (rng_out_sel_sp_ind = $D13) * (rng_out_sel_excl_ind = $E13) * (rng_out_base_post_yr3*rng_out_340B)) + IF([1]Tables!$C$16=[1]Tables!$CF$4, SUMPRODUCT((rng_out_mail_ind = $B13) * (rng_out_sel_sp_ind = $D13) * (rng_out_sel_excl_ind = $F13) * (rng_out_base_post_yr3*rng_out_340B)), 0))/[1]Tables!$AT$4)/AS13, 0)} -> 0 | DL13: {=IFERROR(((SUMPRODUCT((rng_out_mail_ind = $B13) * (rng_out_sel_sp_ind = $D13) * (rng_out_sel_excl_ind = $E13) * (rng_out_base_post_yr4*rng_out_340B)) + IF([1]Tables!$C$16=[1]Tables!$CF$4, SUMPRODUCT((rng_out_mail_ind = $B13) * (rng_out_sel_sp_ind = $D13) * (rng_out_sel_excl_ind = $F13) * (rng_out_base_post_yr4*rng_out_340B)), 0))/[1]Tables!$AT$4)/AT13, 0)} -> 0 | DM13: {=IFERROR(((SUMPRODUCT((rng_out_mail_ind = $B13) * (rng_out_sel_sp_ind = $D13) * (rng_out_sel_excl_ind = $E13) * (rng_out_base_post_yr5*rng_out_340B)) + IF([1]Tables!$C$16=[1]Tables!$CF$4, SUMPRODUCT((rng_out_mail_ind = $B13) * (rng_out_sel_sp_ind = $D13) * (rng_out_sel_excl_ind = $F13) * (rng_out_base_post_yr5*rng_out_340B)), 0))/[1]Tables!$AT$4)/AU13, 0)} -> 0
D14: Y | E14: N | F14: Y | H14: Specialty | I14: {=SUMIFS(INDIRECT('[1]RA Output'!BP$1), rng_out_sel_sp_ind, $D14, rng_out_sel_excl_ind,$E14) + SUMIFS(INDIRECT('[1]RA Output'!BP$1), rng_out_sel_sp_ind, $D14, rng_out_sel_excl_ind,$F14, rng_out_sel_excl_yr_ind, ">0") + IF([1]Tables!$C$16=[1]Tables!$CF$4, SUMIFS(INDIRECT('[1]RA Output'!BP$1), rng_out_sel_sp_ind, $D14, rng_out_sel_excl_ind,$F14, rng_out_sel_excl_yr_ind, ""), 0)} -> #REF! | J14: {=SUMIFS(INDIRECT('[1]RA Output'!BQ$1), rng_out_sel_sp_ind, $D14, rng_out_sel_excl_ind,$E14) + SUMIFS(INDIRECT('[1]RA Output'!BQ$1), rng_out_sel_sp_ind, $D14, rng_out_sel_excl_ind,$F14, rng_out_sel_excl_yr_ind, ">0") + IF([1]Tables!$C$16=[1]Tables!$CF$4, SUMIFS(INDIRECT('[1]RA Output'!BQ$1), rng_out_sel_sp_ind, $D14, rng_out_sel_excl_ind,$F14, rng_out_sel_excl_yr_ind, ""), 0)} -> #REF! | K14: {=SUMIFS(INDIRECT('[1]RA Output'!BR$1), rng_out_sel_sp_ind, $D14, rng_out_sel_excl_ind,$E14) + SUMIFS(INDIRECT('[1]RA Output'!BR$1), rng_out_sel_sp_ind, $D14, rng_out_sel_excl_ind,$F14, rng_out_sel_excl_yr_ind, ">0") + IF([1]Tables!$C$16=[1]Tables!$CF$4, SUMIFS(INDIRECT('[1]RA Output'!BR$1), rng_out_sel_sp_ind, $D14, rng_out_sel_excl_ind,$F14, rng_out_sel_excl_yr_ind, ""), 0)} -> #REF! | L14: {=SUMIFS(INDIRECT('[1]RA Output'!BS$1), rng_out_sel_sp_ind, $D14, rng_out_sel_excl_ind,$E14) + SUMIFS(INDIRECT('[1]RA Output'!BS$1), rng_out_sel_sp_ind, $D14, rng_out_sel_excl_ind,$F14, rng_out_sel_excl_yr_ind, ">0") + IF([1]Tables!$C$16=[1]Tables!$CF$4, SUMIFS(INDIRECT('[1]RA Output'!BS$1), rng_out_sel_sp_ind, $D14, rng_out_sel_excl_ind,$F14, rng_out_sel_excl_yr_ind, ""), 0)} -> #REF! | M14: {=SUMIFS(INDIRECT('[1]RA Output'!BT$1), rng_out_sel_sp_ind, $D14, rng_out_sel_excl_ind,$E14) + SUMIFS(INDIRECT('[1]RA Output'!BT$1), rng_out_sel_sp_ind, $D14, rng_out_sel_excl_ind,$F14, rng_out_sel_excl_yr_ind, ">0") + IF([1]Tables!$C$16=[1]Tables!$CF$4, SUMIFS(INDIRECT('[1]RA Output'!BT$1), rng_out_sel_sp_ind, $D14, rng_out_sel_excl_ind,$F14, rng_out_sel_excl_yr_ind, ""), 0)} -> #REF! | N14: =IFERROR(I14/N$61, 0) -> 0 | O14: =IFERROR(J14/O$61, 0) -> 0 | P14: =IFERROR(K14/P$61, 0) -> 0 | Q14: =IFERROR(L14/Q$61, 0) -> 0 | R14: =IFERROR(M14/R$61, 0) -> 0 | S14: =IFERROR(I14/S$61, 0) -> 0 | T14: =IFERROR(J14/T$61, 0) -> 0 | U14: =IFERROR(K14/U$61, 0) -> 0 | V14: =IFERROR(L14/V$61, 0) -> 0 | W14: =IFERROR(M14/W$61, 0) -> 0 | Y14: Specialty | Z14: =IFERROR(I14/[1]Tables!$AT$4,0) -> 0 | AA14: =IFERROR(J14/[1]Tables!$AT$4,0) -> 0 | AB14: =IFERROR(K14/[1]Tables!$AT$4,0) -> 0 | AC14: =IFERROR(L14/[1]Tables!$AT$4,0) -> 0 | AD14: =IFERROR(M14/[1]Tables!$AT$4,0) -> 0 | AE14: =IFERROR(N14/[1]Tables!$AT$4, 0) -> 0 | AF14: =IFERROR(O14/[1]Tables!$AT$4, 0) -> 0 | AG14: =IFERROR(P14/[1]Tables!$AT$4, 0) -> 0 | AH14: =IFERROR(Q14/[1]Tables!$AT$4, 0) -> 0 | AI14: =IFERROR(R14/[1]Tables!$AT$4, 0) -> 0 | AJ14: =IFERROR(S14/[1]Tables!$AT$4,0) -> 0 | AK14: =IFERROR(T14/[1]Tables!$AT$4,0) -> 0 | AL14: =IFERROR(U14/[1]Tables!$AT$4,0) -> 0 | AM14: =IFERROR(V14/[1]Tables!$AT$4,0) -> 0 | AN14: =IFERROR(W14/[1]Tables!$AT$4,0) -> 0 | AP14: Specialty | AQ14: {=(SUMIFS(INDIRECT('[1]RA Output'!CP$1), rng_out_sel_sp_ind, $D14, rng_out_sel_excl_ind,$E14) + SUMIFS(INDIRECT('[1]RA Output'!CP$1), rng_out_sel_sp_ind, $D14, rng_out_sel_excl_ind,$F14, rng_out_sel_excl_yr_ind, ">0") + IF([1]Tables!$C$16=[1]Tables!$CF$4, SUMIFS(INDIRECT('[1]RA Output'!CP$1), rng_out_sel_sp_ind, $D14, rng_out_sel_excl_ind,$F14, rng_out_sel_excl_yr_ind, ""), 0))/[1]Tables!$AT$4} -> #REF! | AR14: {=(SUMIFS(INDIRECT('[1]RA Output'!CQ$1), rng_out_sel_sp_ind, $D14, rng_out_sel_excl_ind,$E14) + SUMIFS(INDIRECT('[1]RA Output'!CQ$1), rng_out_sel_sp_ind, $D14, rng_out_sel_excl_ind,$F14, rng_out_sel_excl_yr_ind, ">0") + IF([1]Tables!$C$16=[1]Tables!$CF$4, SUMIFS(INDIRECT('[1]RA Output'!CQ$1), rng_out_sel_sp_ind, $D14, rng_out_sel_excl_ind,$F14, rng_out_sel_excl_yr_ind, ""), 0))/[1]Tables!$AT$4} -> #REF! | AS14: {=(SUMIFS(INDIRECT('[1]RA Output'!CR$1), rng_out_sel_sp_ind, $D14, rng_out_sel_excl_ind,$E14) + SUMIFS(INDIRECT('[1]RA Output'!CR$1), rng_out_sel_sp_ind, $D14, rng_out_sel_excl_ind,$F14, rng_out_sel_excl_yr_ind, ">0") + IF([1]Tables!$C$16=[1]Tables!$CF$4, SUMIFS(INDIRECT('[1]RA Output'!CR$1), rng_out_sel_sp_ind, $D14, rng_out_sel_excl_ind,$F14, rng_out_sel_excl_yr_ind, ""), 0))/[1]Tables!$AT$4} -> #REF! | AT14: {=(SUMIFS(INDIRECT('[1]RA Output'!CS$1), rng_out_sel_sp_ind, $D14, rng_out_sel_excl_ind,$E14) + SUMIFS(INDIRECT('[1]RA Output'!CS$1), rng_out_sel_sp_ind, $D14, rng_out_sel_excl_ind,$F14, rng_out_sel_excl_yr_ind, ">0") + IF([1]Tables!$C$16=[1]Tables!$CF$4, SUMIFS(INDIRECT('[1]RA Output'!CS$1), rng_out_sel_sp_ind, $D14, rng_out_sel_excl_ind,$F14, rng_out_sel_excl_yr_ind, ""), 0))/[1]Tables!$AT$4} -> #REF! | AU14: {=(SUMIFS(INDIRECT('[1]RA Output'!CT$1), rng_out_sel_sp_ind, $D14, rng_out_sel_excl_ind,$E14) + SUMIFS(INDIRECT('[1]RA Output'!CT$1), rng_out_sel_sp_ind, $D14, rng_out_sel_excl_ind,$F14, rng_out_sel_excl_yr_ind, ">0") + IF([1]Tables!$C$16=[1]Tables!$CF$4, SUMIFS(INDIRECT('[1]RA Output'!CT$1), rng_out_sel_sp_ind, $D14, rng_out_sel_excl_ind,$F14, rng_out_sel_excl_yr_ind, ""), 0))/[1]Tables!$AT$4} -> #REF! | AV14: =IFERROR(AQ14/AV$61, 0) -> 0 | AW14: =IFERROR(AR14/AW$61, 0) -> 0 | AX14: =IFERROR(AS14/AX$61, 0) -> 0 | AY14: =IFERROR(AT14/AY$61, 0) -> 0 | AZ14: =IFERROR(AU14/AZ$61, 0) -> 0 | BA14: =IFERROR(AQ14/BA$61, 0) -> 0 | BB14: =IFERROR(AR14/BB$61, 0) -> 0 | BC14: =IFERROR(AS14/BC$61, 0) -> 0 | BD14: =IFERROR(AT14/BD$61, 0) -> 0 | BE14: =IFERROR(AU14/BE$61, 0) -> 0 | BG14: Specialty | BH14: {=(SUMIFS(INDIRECT('[1]RA Output'!DP$1), rng_out_sel_sp_ind, $D14, rng_out_sel_excl_ind,$E14) + SUMIFS(INDIRECT('[1]RA Output'!DP$1), rng_out_sel_sp_ind, $D14, rng_out_sel_excl_ind,$F14, rng_out_sel_excl_yr_ind, ">0") + IF([1]Tables!$C$16=[1]Tables!$CF$4, SUMIFS(INDIRECT('[1]RA Output'!DP$1), rng_out_sel_sp_ind, $D14, rng_out_sel_excl_ind,$F14,rng_out_sel_excl_yr_ind, ""), 0))/[1]Tables!$AT$4} -> #REF! | BI14: {=(SUMIFS(INDIRECT('[1]RA Output'!DQ$1), rng_out_sel_sp_ind, $D14, rng_out_sel_excl_ind,$E14) + SUMIFS(INDIRECT('[1]RA Output'!DQ$1), rng_out_sel_sp_ind, $D14, rng_out_sel_excl_ind,$F14, rng_out_sel_excl_yr_ind, ">0") + IF([1]Tables!$C$16=[1]Tables!$CF$4, SUMIFS(INDIRECT('[1]RA Output'!DQ$1), rng_out_sel_sp_ind, $D14, rng_out_sel_excl_ind,$F14,rng_out_sel_excl_yr_ind, ""), 0))/[1]Tables!$AT$4} -> #REF! | BJ14: {=(SUMIFS(INDIRECT('[1]RA Output'!DR$1), rng_out_sel_sp_ind, $D14, rng_out_sel_excl_ind,$E14) + SUMIFS(INDIRECT('[1]RA Output'!DR$1), rng_out_sel_sp_ind, $D14, rng_out_sel_excl_ind,$F14, rng_out_sel_excl_yr_ind, ">0") + IF([1]Tables!$C$16=[1]Tables!$CF$4, SUMIFS(INDIRECT('[1]RA Output'!DR$1), rng_out_sel_sp_ind, $D14, rng_out_sel_excl_ind,$F14,rng_out_sel_excl_yr_ind, ""), 0))/[1]Tables!$AT$4} -> #REF! | BK14: {=(SUMIFS(INDIRECT('[1]RA Output'!DS$1), rng_out_sel_sp_ind, $D14, rng_out_sel_excl_ind,$E14) + SUMIFS(INDIRECT('[1]RA Output'!DS$1), rng_out_sel_sp_ind, $D14, rng_out_sel_excl_ind,$F14, rng_out_sel_excl_yr_ind, ">0") + IF([1]Tables!$C$16=[1]Tables!$CF$4, SUMIFS(INDIRECT('[1]RA Output'!DS$1), rng_out_sel_sp_ind, $D14, rng_out_sel_excl_ind,$F14,rng_out_sel_excl_yr_ind, ""), 0))/[1]Tables!$AT$4} -> #REF! | BL14: {=(SUMIFS(INDIRECT('[1]RA Output'!DT$1), rng_out_sel_sp_ind, $D14, rng_out_sel_excl_ind,$E14) + SUMIFS(INDIRECT('[1]RA Output'!DT$1), rng_out_sel_sp_ind, $D14, rng_out_sel_excl_ind,$F14, rng_out_sel_excl_yr_ind, ">0") + IF([1]Tables!$C$16=[1]Tables!$CF$4, SUMIFS(INDIRECT('[1]RA Output'!DT$1), rng_out_sel_sp_ind, $D14, rng_out_sel_excl_ind,$F14,rng_out_sel_excl_yr_ind, ""), 0))/[1]Tables!$AT$4} -> #REF! | BM14: =IFERROR(BH14/BM$61, 0) -> 0 | BN14: =IFERROR(BI14/BN$61, 0) -> 0 | BO14: =IFERROR(BJ14/BO$61, 0) -> 0 | BP14: =IFERROR(BK14/BP$61, 0) -> 0 | BQ14: =IFERROR(BL14/BQ$61, 0) -> 0 | BR14: =IFERROR(BH14/BR$61, 0) -> 0 | BS14: =IFERROR(BI14/BS$61, 0) -> 0 | BT14: =IFERROR(BJ14/BT$61, 0) -> 0 | BU14: =IFERROR(BK14/BU$61, 0) -> 0 | BV14: =IFERROR(BL14/BV$61, 0) -> 0 | BX14: Specialty | BY14: =CD14*CD61 -> #VALUE! | BZ14: =CE14*CE61 -> #VALUE! | CA14: =CF14*CF61 -> #VALUE! | CB14: =CG14*CG61 -> #VALUE! | CC14: =CH14*CH61 -> #VALUE! | CD14: =BM14-DC14 -> 0 | CE14: =BN14-DD14 -> 0 | CF14: =BO14-DE14 -> 0 | CG14: =BP14-DF14 -> 0 | CH14: =BQ14-DG14 -> 0 | CI14: =IFERROR(BY14/CI61, 0) -> 0 | CJ14: =IFERROR(BZ14/CJ61, 0) -> 0 | CK14: =IFERROR(CA14/CK61, 0) -> 0 | CL14: =IFERROR(CB14/CL61, 0) -> 0 | CM14: =IFERROR(CC14/CM61, 0) -> 0 | DC14: {=IFERROR(BM14-BM14*BR70*(1-INDEX([1]Tables!$EA$4:$EE$60,MATCH([1]Tables!$C$22&$BX14,[1]Tables!$EA$4:$EA$60,0),[1]Tables!$EE$1))*(1-DI14)/CD61, 0)} -> 0 | DD14: {=IFERROR(BN14-BN14*BS70*(1-INDEX([1]Tables!$EA$4:$EE$60,MATCH([1]Tables!$C$22&$BX14,[1]Tables!$EA$4:$EA$60,0),[1]Tables!$EE$1))*(1-DJ14)/CE61, 0)} -> 0 | DE14: {=IFERROR(BO14-BO14*BT70*(1-INDEX([1]Tables!$EA$4:$EE$60,MATCH([1]Tables!$C$22&$BX14,[1]Tables!$EA$4:$EA$60,0),[1]Tables!$EE$1))*(1-DK14)/CF61, 0)} -> 0 | DF14: {=IFERROR(BP14-BP14*BU70*(1-INDEX([1]Tables!$EA$4:$EE$60,MATCH([1]Tables!$C$22&$BX14,[1]Tables!$EA$4:$EA$60,0),[1]Tables!$EE$1))*(1-DL14)/CG61, 0)} -> 0 | DG14: {=IFERROR(BQ14-BQ14*BV70*(1-INDEX([1]Tables!$EA$4:$EE$60,MATCH([1]Tables!$C$22&$BX14,[1]Tables!$EA$4:$EA$60,0),[1]Tables!$EE$1))*(1-DM14)/CH61, 0)} -> 0 | DI14: {=IFERROR(((SUMPRODUCT((rng_out_sel_sp_ind = $D14) * (rng_out_sel_excl_ind = $E14) * (rng_out_base_post_yr1*rng_out_340B)) + IF([1]Tables!$C$16=[1]Tables!$CF$4, SUMPRODUCT((rng_out_sel_sp_ind = $D14) * (rng_out_sel_excl_ind = $F14) * (rng_out_base_post_yr1*rng_out_340B)), 0))/[1]Tables!$AT$4)/AQ14, 0)} -> 0 | DJ14: {=IFERROR(((SUMPRODUCT((rng_out_sel_sp_ind = $D14) * (rng_out_sel_excl_ind = $E14) * (rng_out_base_post_yr2*rng_out_340B)) + IF([1]Tables!$C$16=[1]Tables!$CF$4, SUMPRODUCT((rng_out_sel_sp_ind = $D14) * (rng_out_sel_excl_ind = $F14) * (rng_out_base_post_yr2*rng_out_340B)), 0))/[1]Tables!$AT$4)/AR14, 0)} -> 0 | DK14: {=IFERROR(((SUMPRODUCT((rng_out_sel_sp_ind = $D14) * (rng_out_sel_excl_ind = $E14) * (rng_out_base_post_yr3*rng_out_340B)) + IF([1]Tables!$C$16=[1]Tables!$CF$4, SUMPRODUCT((rng_out_sel_sp_ind = $D14) * (rng_out_sel_excl_ind = $F14) * (rng_out_base_post_yr3*rng_out_340B)), 0))/[1]Tables!$AT$4)/AS14, 0)} -> 0 | DL14: {=IFERROR(((SUMPRODUCT((rng_out_sel_sp_ind = $D14) * (rng_out_sel_excl_ind = $E14) * (rng_out_base_post_yr4*rng_out_340B)) + IF([1]Tables!$C$16=[1]Tables!$CF$4, SUMPRODUCT((rng_out_sel_sp_ind = $D14) * (rng_out_sel_excl_ind = $F14) * (rng_out_base_post_yr4*rng_out_340B)), 0))/[1]Tables!$AT$4)/AT14, 0)} -> 0 | DM14: {=IFERROR(((SUMPRODUCT((rng_out_sel_sp_ind = $D14) * (rng_out_sel_excl_ind = $E14) * (rng_out_base_post_yr5*rng_out_340B)) + IF([1]Tables!$C$16=[1]Tables!$CF$4, SUMPRODUCT((rng_out_sel_sp_ind = $D14) * (rng_out_sel_excl_ind = $F14) * (rng_out_base_post_yr5*rng_out_340B)), 0))/[1]Tables!$AT$4)/AU14, 0)} -> 0
H15: Total | I15: =SUM(I11:I14) -> #REF! | J15: =SUM(J11:J14) -> #REF! | K15: =SUM(K11:K14) -> #REF! | L15: =SUM(L11:L14) -> #REF! | M15: =SUM(M11:M14) -> #REF! | N15: =IFERROR(I15/N$62, 0) -> 0 | O15: =IFERROR(J15/O$62, 0) -> 0 | P15: =IFERROR(K15/P$62, 0) -> 0 | Q15: =IFERROR(L15/Q$62, 0) -> 0 | R15: =IFERROR(M15/R$62, 0) -> 0 | S15: =IFERROR(I15/S$62, 0) -> 0 | T15: =IFERROR(J15/T$62, 0) -> 0 | U15: =IFERROR(K15/U$62, 0) -> 0 | V15: =IFERROR(L15/V$62, 0) -> 0 | W15: =IFERROR(M15/W$62, 0) -> 0 | Y15: Total | Z15: =SUM(Z11:Z14) -> 0 | AA15: =SUM(AA11:AA14) -> 0 | AB15: =SUM(AB11:AB14) -> 0 | AC15: =SUM(AC11:AC14) -> 0 | AD15: =SUM(AD11:AD14) -> 0 | AE15: =IFERROR(N15/[1]Tables!$AT$4, 0) -> 0 | AF15: =IFERROR(O15/[1]Tables!$AT$4, 0) -> 0 | AG15: =IFERROR(P15/[1]Tables!$AT$4, 0) -> 0 | AH15: =IFERROR(Q15/[1]Tables!$AT$4, 0) -> 0 | AI15: =IFERROR(R15/[1]Tables!$AT$4, 0) -> 0 | AJ15: =IFERROR(S15/[1]Tables!$AT$4,0) -> 0 | AK15: =IFERROR(T15/[1]Tables!$AT$4,0) -> 0 | AL15: =IFERROR(U15/[1]Tables!$AT$4,0) -> 0 | AM15: =IFERROR(V15/[1]Tables!$AT$4,0) -> 0 | AN15: =IFERROR(W15/[1]Tables!$AT$4,0) -> 0 | AP15: Total | AQ15: =SUM(AQ11:AQ14) -> #REF! | AR15: =SUM(AR11:AR14) -> #REF! | AS15: =SUM(AS11:AS14) -> #REF! | AT15: =SUM(AT11:AT14) -> #REF! | AU15: =SUM(AU11:AU14) -> #REF! | AV15: =IFERROR(AQ15/AV$62, 0) -> 0 | AW15: =IFERROR(AR15/AW$62, 0) -> 0 | AX15: =IFERROR(AS15/AX$62, 0) -> 0 | AY15: =IFERROR(AT15/AY$62, 0) -> 0 | AZ15: =IFERROR(AU15/AZ$62, 0) -> 0 | BA15: =IFERROR(AQ15/BA$62, 0) -> 0 | BB15: =IFERROR(AR15/BB$62, 0) -> 0 | BC15: =IFERROR(AS15/BC$62, 0) -> 0 | BD15: =IFERROR(AT15/BD$62, 0) -> 0 | BE15: =IFERROR(AU15/BE$62, 0) -> 0 | BG15: Total | BH15: =SUM(BH11:BH14) -> #REF! | BI15: =SUM(BI11:BI14) -> #REF! | BJ15: =SUM(BJ11:BJ14) -> #REF! | BK15: =SUM(BK11:BK14) -> #REF! | BL15: =SUM(BL11:BL14) -> #REF! | BM15: =IFERROR(BH15/BM$62, 0) -> 0 | BN15: =IFERROR(BI15/BN$62, 0) -> 0 | BO15: =IFERROR(BJ15/BO$62, 0) -> 0 | BP15: =IFERROR(BK15/BP$62, 0) -> 0 | BQ15: =IFERROR(BL15/BQ$62, 0) -> 0 | BR15: =IFERROR(BH15/BR$62, 0) -> 0 | BS15: =IFERROR(BI15/BS$62, 0) -> 0 | BT15: =IFERROR(BJ15/BT$62, 0) -> 0 | BU15: =IFERROR(BK15/BU$62, 0) -> 0 | BV15: =IFERROR(BL15/BV$62, 0) -> 0 | BX15: Total | BY15: =SUM(BY11:BY14) -> #VALUE! | BZ15: =SUM(BZ11:BZ14) -> #VALUE! | CA15: =SUM(CA11:CA14) -> #VALUE! | CB15: =SUM(CB11:CB14) -> #VALUE! | CC15: =SUM(CC11:CC14) -> #VALUE! | CD15: =IFERROR(BY15/CD62, 0) -> 0 | CE15: =IFERROR(BZ15/CE62, 0) -> 0 | CF15: =IFERROR(CA15/CF62, 0) -> 0 | CG15: =IFERROR(CB15/CG62, 0) -> 0 | CH15: =IFERROR(CC15/CH62, 0) -> 0 | CI15: =IFERROR(BY15/CI62, 0) -> 0 | CJ15: =IFERROR(BZ15/CJ62, 0) -> 0 | CK15: =IFERROR(CA15/CK62, 0) -> 0 | CL15: =IFERROR(CB15/CL62, 0) -> 0 | CM15: =IFERROR(CC15/CM62, 0) -> 0
I17: MAF | Z17: MAF | AQ17: MAF | BH17: MAF | BY17: MAF | DC17: MAF | DI17: MAF
